Workbook

Sheet MENU
A4: 1 | B4: ESPUMITA DE LIMON | D4: 21 | E4: Nombre de la receta 21 | G4: 41 | H4: Nombre de la receta 41
A5: 2 | B5: CARROT CAKE | D5: 22 | E5: Nombre de la receta 22 | G5: 42 | H5: Nombre de la receta 42
A6: 3 | B6: PEPAS INTEGRALES | D6: 23 | E6: Nombre de la receta 23 | G6: 43 | H6: Nombre de la receta 43
A7: 4 | B7: Nombre de la receta 4 | D7: 24 | E7: Nombre de la receta 24 | G7: 44 | H7: Nombre de la receta 44
A8: 5 | B8: Nombre de la receta 5 | D8: 25 | E8: Nombre de la receta 25 | G8: 45 | H8: Nombre de la receta 45
A9: 6 | B9: Nombre de la receta 6 | D9: 26 | E9: Nombre de la receta 26 | G9: 46 | H9: Nombre de la receta 46
A10: 7 | B10: Nombre de la receta 7 | D10: 27 | E10: Nombre de la receta 27 | G10: 47 | H10: Nombre de la receta 47
A11: 8 | B11: Nombre de la receta 8 | D11: 28 | E11: Nombre de la receta 28 | G11: 48 | H11: Nombre de la receta 48
A12: 9 | B12: Nombre de la receta 9 | D12: 29 | E12: Nombre de la receta 29 | G12: 49 | H12: Nombre de la receta 49
A13: 10 | B13: Nombre de la receta 10 | D13: 30 | E13: Nombre de la receta 30 | G13: 50 | H13: Nombre de la receta 50
A14: 11 | B14: Nombre de la receta 11 | D14: 31 | E14: Nombre de la receta 31 | G14: 51 | H14: Nombre de la receta 51
A15: 12 | B15: Nombre de la receta 12 | D15: 32 | E15: Nombre de la receta 32 | G15: 52 | H15: Nombre de la receta 52
... A23: 20 | B23: Nombre de la receta 20 | D23: 40 | E23: Nombre de la receta 40 | G23: 60 | H23: Nombre de la receta 60

Sheet Ingredientes
B2: INGREDIENTES PARA LAS RECETAS
B4: INGREDIENTES | C4: PRECIO | D4: U. MEDIDA | E4: CATEGORÍA
B5: MANTECA | C5: 10066.2 | D5: KG | E5: LACTEOS
B6: DULCE DE LECHE FF | C6: 4100 | D6: KG | E6: Carnes
B7: Azucar | C7: 1132 | D7: KG | E7: Carnes
B8: Harina 0000 | C8: 1106 | D8: KG | E8: Harinas
C9: 0 | D9: KG | E9: Grasas
B10: Huevo | C10: 150 | D10: KG | E10: Almacen
B11: CACAO | C11: 16500 | D11: KG | E11: Fiambres
B12: Queso Cheddar | C12: 9000 | D12: KG | E12: Fiambres
B13: AZUCAR RUBIA | C13: 8847 | D13: KG | E13: Fiambres
B14: PASTA NUTELA | C14: 9500 | D14: KG | E14: Fiambres
B15: CHIPS BLACO | C15: 6855 | D15: KG | E15: Panaderia
B16: Azucar | C16: 650 | D16: KG | E16: Varios
B17: HARINA LFEUDANTE | C17: 1318 | D17: KG | E17: Fiambres
B18: OREOS PAQUETE | C18: 1265 | D18: UN | E18: Fiambres
B19: CHIPS NEGRFOS | C19: 7510 | D19: UN | E19: Descartables
B20: NUTELA | C20: 70 | D20: UN | E20: Descartables
B21: PASTA BON O BON | C21: 1880 | D21: KG | E21: Panaderia
B22: BARRA BON O BON | C22: 184
B23: MINI OREO | C23: 8741 | D23: KG
B24: CHOCOLATE COBERTURA | C24: 25000
B25: NUECES | C25: 22629
B26: VAINILLA | C26: 3000
B27: VICARBONATO | C27: 11000
B28: VINAGRE | C28: 3428
B29: POLVO DE HORNEAR | C29: 22000
B30: MAIZENA | C30: 4000
B31: CREMA DE LECHE | C31: 9565.3
B32: AZUCAR IMPALPABLE | C32: 16022.4
B33: PASAS UVAS | C33: 4320
B34: NARANJA 315 | C34: 315
B35: LIMON | C35: 344
... B45: CANELA | C45: 0
C46: 0
C47: 0
C48: 0

Sheet MO
C1: COSTOS LABORALES
B3: EMPLEADOS | C3: Sueldo mensual | D3: Horas trabajadas en el mes | E3: Costo por hora
B4: Empleado 1 | C4: 1100000 | D4: 200 | E4: 1100000
B5: Empleado 2 | C5: 0 | D5: 0 | E5: 0
B6: Sueldo personal | C6: 0 | D6: 0 | E6: 0
E7: =IFERROR(C7/D7,0) -> 0
E8: =IFERROR(C8/D8,0) -> 0
E9: =IFERROR(C9/D9,0) -> 0
E10: =IFERROR(C10/D10,0) -> 0
E11: =IFERROR(C11/D11,0) -> 0
E12: =IFERROR(C12/D12,0) -> 0
E13: =IFERROR(C13/D13,0) -> 0
E14: =IFERROR(C14/D14,0) -> 0
E15: =IFERROR(C15/D15,0) -> 0
E16: =IFERROR(C16/D16,0) -> 0
E17: =IFERROR(C17/D17,0) -> 0
C18: =SUM(C4:C17) -> 1100000 | D18: =SUM(D4:D17) -> 200 | E18: =SUM(E4:E17) -> 1100000

Sheet CIF
B2: COSTOS FIJOS | C2: RECETAS TOTALES PRODUCIDAS POR MES | D2: =G64 -> 0
B3: CONCEPTO | C3: Monto mensual | D3: Costo fijo por unidad | F3: PRODUCTO | G3: Recetas producidas en el mes | H3: % de los Costos fijos absorbidos | I3: Costos fijos por receta
B4: Alquiler Local | C4: 800000 | D4: =IFERROR(C4/$D$2,"") | E4: 1 | F4: =MENU!B4 -> ESPUMITA DE LIMON | H4: =IFERROR(G4/$D$2,"") | I4: =IFERROR(H4*$D$67,"")
B5: Servicios públicos | C5: 200000 | D5: =IFERROR(C5/$D$2,"") | E5: 2 | F5: =MENU!B5 -> CARROT CAKE | H5: =IFERROR(G5/$D$2,"") | I5: =IFERROR(H5*$D$67,"")
B6: Internet y telefonía fija | C6: 40000 | D6: =IFERROR(C6/$D$2,"") | E6: 3 | F6: =MENU!B6 -> PEPAS INTEGRALES | H6: =IFERROR(G6/$D$2,"") | I6: =IFERROR(H6*$D$67,"")
B7: Honorarios contador | C7: 30000 | D7: =IFERROR(C7/$D$2,"") | E7: 4 | F7: =MENU!B7 -> Nombre de la receta 4 | H7: =IFERROR(G7/$D$2,"") | I7: =IFERROR(H7*$D$67,"")
B8: Honorarios legales | C8: 20000 | D8: =IFERROR(C8/$D$2,"") | E8: 5 | F8: =MENU!B8 -> Nombre de la receta 5 | H8: =IFERROR(G8/$D$2,"") | I8: =IFERROR(H8*$D$67,"")
B9: Seguros | C9: 30000 | D9: =IFERROR(C9/$D$2,"") | E9: 6 | F9: =MENU!B9 -> Nombre de la receta 6 | H9: =IFERROR(G9/$D$2,"") | I9: =IFERROR(H9*$D$67,"")
B10: Seguridad | C10: 20000 | D10: =IFERROR(C10/$D$2,"") | E10: 7 | F10: =MENU!B10 -> Nombre de la receta 7 | H10: =IFERROR(G10/$D$2,"") | I10: =IFERROR(H10*$D$67,"")
B11: Expensas | C11: 40000 | D11: =IFERROR(C11/$D$2,"") | E11: 8 | F11: =MENU!B11 -> Nombre de la receta 8 | H11: =IFERROR(G11/$D$2,"") | I11: =IFERROR(H11*$D$67,"")
D12: =IFERROR(C12/$D$2,"") | E12: 9 | F12: =MENU!B12 -> Nombre de la receta 9 | H12: =IFERROR(G12/$D$2,"") | I12: =IFERROR(H12*$D$67,"")
D13: =IFERROR(C13/$D$2,"") | E13: 10 | F13: =MENU!B13 -> Nombre de la receta 10 | H13: =IFERROR(G13/$D$2,"") | I13: =IFERROR(H13*$D$67,"")
D14: =IFERROR(C14/$D$2,"") | E14: 11 | F14: =MENU!B14 -> Nombre de la receta 11 | H14: =IFERROR(G14/$D$2,"") | I14: =IFERROR(H14*$D$67,"")
D15: =IFERROR(C15/$D$2,"") | E15: 12 | F15: =MENU!B15 -> Nombre de la receta 12 | H15: =IFERROR(G15/$D$2,"") | I15: =IFERROR(H15*$D$67,"")
D16: =IFERROR(C16/$D$2,"") | E16: 13 | F16: =MENU!B16 -> Nombre de la receta 13 | H16: =IFERROR(G16/$D$2,"") | I16: =IFERROR(H16*$D$67,"")
D17: =IFERROR(C17/$D$2,"") | E17: 14 | F17: =MENU!B17 -> Nombre de la receta 14 | H17: =IFERROR(G17/$D$2,"") | I17: =IFERROR(H17*$D$67,"")
D18: =IFERROR(C18/$D$2,"") | E18: 15 | F18: =MENU!B18 -> Nombre de la receta 15 | H18: =IFERROR(G18/$D$2,"") | I18: =IFERROR(H18*$D$67,"")
D19: =IFERROR(C19/$D$2,"") | E19: 16 | F19: =MENU!B19 -> Nombre de la receta 16 | H19: =IFERROR(G19/$D$2,"") | I19: =IFERROR(H19*$D$67,"")
D20: =IFERROR(C20/$D$2,"") | E20: 17 | F20: =MENU!B20 -> Nombre de la receta 17 | H20: =IFERROR(G20/$D$2,"") | I20: =IFERROR(H20*$D$67,"")
D21: =IFERROR(C21/$D$2,"") | E21: 18 | F21: =MENU!B21 -> Nombre de la receta 18 | H21: =IFERROR(G21/$D$2,"") | I21: =IFERROR(H21*$D$67,"")
D22: =IFERROR(C22/$D$2,"") | E22: 19 | F22: =MENU!B22 -> Nombre de la receta 19 | H22: =IFERROR(G22/$D$2,"") | I22: =IFERROR(H22*$D$67,"")
D23: =IFERROR(C23/$D$2,"") | E23: 20 | F23: =MENU!B23 -> Nombre de la receta 20 | H23: =IFERROR(G23/$D$2,"") | I23: =IFERROR(H23*$D$67,"")
D24: =IFERROR(C24/$D$2,"") | E24: 21 | F24: =MENU!E4 -> Nombre de la receta 21 | H24: =IFERROR(G24/$D$2,"") | I24: =IFERROR(H24*$D$67,"")
D25: =IFERROR(C25/$D$2,"") | E25: 22 | F25: =MENU!E5 -> Nombre de la receta 22 | H25: =IFERROR(G25/$D$2,"") | I25: =IFERROR(H25*$D$67,"")
D26: =IFERROR(C26/$D$2,"") | E26: 23 | F26: =MENU!E6 -> Nombre de la receta 23 | H26: =IFERROR(G26/$D$2,"") | I26: =IFERROR(H26*$D$67,"")
D27: =IFERROR(C27/$D$2,"") | E27: 24 | F27: =MENU!E7 -> Nombre de la receta 24 | H27: =IFERROR(G27/$D$2,"") | I27: =IFERROR(H27*$D$67,"")
D28: =IFERROR(C28/$D$2,"") | E28: 25 | F28: =MENU!E8 -> Nombre de la receta 25 | H28: =IFERROR(G28/$D$2,"") | I28: =IFERROR(H28*$D$67,"")
D29: =IFERROR(C29/$D$2,"") | E29: 26 | F29: =MENU!E9 -> Nombre de la receta 26 | H29: =IFERROR(G29/$D$2,"") | I29: =IFERROR(H29*$D$67,"")
D30: =IFERROR(C30/$D$2,"") | E30: 27 | F30: =MENU!E10 -> Nombre de la receta 27 | H30: =IFERROR(G30/$D$2,"") | I30: =IFERROR(H30*$D$67,"")
D31: =IFERROR(C31/$D$2,"") | E31: 28 | F31: =MENU!E11 -> Nombre de la receta 28 | H31: =IFERROR(G31/$D$2,"") | I31: =IFERROR(H31*$D$67,"")
D32: =IFERROR(C32/$D$2,"") | E32: 29 | F32: =MENU!E12 -> Nombre de la receta 29 | H32: =IFERROR(G32/$D$2,"") | I32: =IFERROR(H32*$D$67,"")
D33: =IFERROR(C33/$D$2,"") | E33: 30 | F33: =MENU!E13 -> Nombre de la receta 30 | H33: =IFERROR(G33/$D$2,"") | I33: =IFERROR(H33*$D$67,"")
D34: =IFERROR(C34/$D$2,"") | E34: 31 | F34: =MENU!E14 -> Nombre de la receta 31 | H34: =IFERROR(G34/$D$2,"") | I34: =IFERROR(H34*$D$67,"")
D35: =IFERROR(C35/$D$2,"") | E35: 32 | F35: =MENU!E15 -> Nombre de la receta 32 | H35: =IFERROR(G35/$D$2,"") | I35: =IFERROR(H35*$D$67,"")
... D43: =IFERROR(C43/$D$2,"") | E43: 40 | F43: =MENU!E23 -> Nombre de la receta 40 | H43: =IFERROR(G43/$D$2,"") | I43: =IFERROR(H43*$D$67,"")
D44: =IFERROR(C44/$D$2,"") | E44: 41 | F44: =MENU!H4 -> Nombre de la receta 41 | H44: =IFERROR(G44/$D$2,"") | I44: =IFERROR(H44*$D$67,"")
D45: =IFERROR(C45/$D$2,"") | E45: 42 | F45: =MENU!H5 -> Nombre de la receta 42 | H45: =IFERROR(G45/$D$2,"") | I45: =IFERROR(H45*$D$67,"")
D46: =IFERROR(C46/$D$2,"") | E46: 43 | F46: =MENU!H6 -> Nombre de la receta 43 | H46: =IFERROR(G46/$D$2,"") | I46: =IFERROR(H46*$D$67,"")
D47: =IFERROR(C47/$D$2,"") | E47: 44 | F47: =MENU!H7 -> Nombre de la receta 44 | H47: =IFERROR(G47/$D$2,"") | I47: =IFERROR(H47*$D$67,"")
D48: =IFERROR(C48/$D$2,"") | E48: 45 | F48: =MENU!H8 -> Nombre de la receta 45 | H48: =IFERROR(G48/$D$2,"") | I48: =IFERROR(H48*$D$67,"")
...

Sheet 1
B2: =MENU!B4 -> ESPUMITA DE LIMON
B4: COSTO DE LOS INGREDIENTES
B5: Ingrediente | C5: Cantidad | D5: U. medida | E5: Precio unitario | F5: Total | H5: RESUMEN FINAL
B6: MANTECA | C6: 0.12 | D6: =IFERROR(VLOOKUP(B6,Ingredientes!$B:$D,3,FALSE),0) -> KG | E6: =IFERROR(VLOOKUP(B6,Ingredientes!$B:$C,2,FALSE),0) -> 10066.2 | F6: =C6*E6 -> 1207.944 | H6: Costo ingredientes: | I6: =F31 -> 6520.044
B7: Azucar | C7: 0.13 | D7: =IFERROR(VLOOKUP(B7,Ingredientes!$B:$D,3,FALSE),0) -> KG | E7: =IFERROR(VLOOKUP(B7,Ingredientes!$B:$C,2,FALSE),0) -> 1132 | F7: =C7*E7 -> 147.16 | H7: Costo laboral: | I7: 6000
B8: HARINA LFEUDANTE | C8: 0.13 | D8: =IFERROR(VLOOKUP(B8,Ingredientes!$B:$D,3,FALSE),0) -> KG | E8: =IFERROR(VLOOKUP(B8,Ingredientes!$B:$C,2,FALSE),0) -> 1318 | F8: =C8*E8 -> 171.34 | H8: Costo fijo: | I8: 4382
B9: Huevo | C9: 2 | D9: =IFERROR(VLOOKUP(B9,Ingredientes!$B:$D,3,FALSE),0) -> KG | E9: =IFERROR(VLOOKUP(B9,Ingredientes!$B:$C,2,FALSE),0) -> 150 | F9: =C9*E9 -> 300 | H9: Costo Total | I9: =SUM($I$6:$I$8) -> 16902.044
B10: LIMON | C10: 2 | D10: =IFERROR(VLOOKUP(B10,Ingredientes!$B:$D,3,FALSE),0) -> 0 | E10: =IFERROR(VLOOKUP(B10,Ingredientes!$B:$C,2,FALSE),0) -> 344 | F10: =C10*E10 -> 688
B11: AZUCAR IMPALPABLE | C11: 0.25 | D11: =IFERROR(VLOOKUP(B11,Ingredientes!$B:$D,3,FALSE),0) -> 0 | E11: =IFERROR(VLOOKUP(B11,Ingredientes!$B:$C,2,FALSE),0) -> 16022.4 | F11: =C11*E11 -> 4005.6 | H11: Precio de venta | I11: 2000000
D12: =IFERROR(VLOOKUP(B12,Ingredientes!$B:$D,3,FALSE),0) -> 0 | E12: =IFERROR(VLOOKUP(B12,Ingredientes!$B:$C,2,FALSE),0) -> 0 | F12: =C12*E12 -> 0 | H12: Utilidad en $ | I12: =I11-I9 -> 1983098
D13: =IFERROR(VLOOKUP(B13,Ingredientes!$B:$D,3,FALSE),0) -> 0 | E13: =IFERROR(VLOOKUP(B13,Ingredientes!$B:$C,2,FALSE),0) -> 0 | F13: =C13*E13 -> 0 | H13: Utilidad en $ | I13: =I12/I11 -> 0.99154898
D14: =IFERROR(VLOOKUP(B14,Ingredientes!$B:$D,3,FALSE),0) -> 0 | E14: =IFERROR(VLOOKUP(B14,Ingredientes!$B:$C,2,FALSE),0) -> 0 | F14: =C14*E14 -> 0 | H14: Punto de equilibrio (u) | I14: =CIF!C67/(I11-I6-I7) -> 0.59371668
D15: =IFERROR(VLOOKUP(B15,Ingredientes!$B:$D,3,FALSE),0) -> 0 | E15: =IFERROR(VLOOKUP(B15,Ingredientes!$B:$C,2,FALSE),0) -> 0 | F15: =C15*E15 -> 0
D16: =IFERROR(VLOOKUP(B16,Ingredientes!$B:$D,3,FALSE),0) -> 0 | E16: =IFERROR(VLOOKUP(B16,Ingredientes!$B:$C,2,FALSE),0) -> 0 | F16: =C16*E16 -> 0
D17: =IFERROR(VLOOKUP(B17,Ingredientes!$B:$D,3,FALSE),0) -> 0 | E17: =IFERROR(VLOOKUP(B17,Ingredientes!$B:$C,2,FALSE),0) -> 0 | F17: =C17*E17 -> 0
D18: =IFERROR(VLOOKUP(B18,Ingredientes!$B:$D,3,FALSE),0) -> 0 | E18: =IFERROR(VLOOKUP(B18,Ingredientes!$B:$C,2,FALSE),0) -> 0 | F18: =C18*E18 -> 0
D19: =IFERROR(VLOOKUP(B19,Ingredientes!$B:$D,3,FALSE),0) -> 0 | E19: =IFERROR(VLOOKUP(B19,Ingredientes!$B:$C,2,FALSE),0) -> 0 | F19: =C19*E19 -> 0
D20: =IFERROR(VLOOKUP(B20,Ingredientes!$B:$D,3,FALSE),0) -> 0 | E20: =IFERROR(VLOOKUP(B20,Ingredientes!$B:$C,2,FALSE),0) -> 0 | F20: =C20*E20 -> 0
D21: =IFERROR(VLOOKUP(B21,Ingredientes!$B:$D,3,FALSE),0) -> 0 | E21: =IFERROR(VLOOKUP(B21,Ingredientes!$B:$C,2,FALSE),0) -> 0 | F21: =C21*E21 -> 0
D22: =IFERROR(VLOOKUP(B22,Ingredientes!$B:$D,3,FALSE),0) -> 0 | E22: =IFERROR(VLOOKUP(B22,Ingredientes!$B:$C,2,FALSE),0) -> 0 | F22: =C22*E22 -> 0
D23: =IFERROR(VLOOKUP(B23,Ingredientes!$B:$D,3,FALSE),0) -> 0 | E23: =IFERROR(VLOOKUP(B23,Ingredientes!$B:$C,2,FALSE),0) -> 0 | F23: =C23*E23 -> 0
D24: =IFERROR(VLOOKUP(B24,Ingredientes!$B:$D,3,FALSE),0) -> 0 | E24: =IFERROR(VLOOKUP(B24,Ingredientes!$B:$C,2,FALSE),0) -> 0 | F24: =C24*E24 -> 0
D25: =IFERROR(VLOOKUP(B25,Ingredientes!$B:$D,3,FALSE),0) -> 0 | E25: =IFERROR(VLOOKUP(B25,Ingredientes!$B:$C,2,FALSE),0) -> 0 | F25: =C25*E25 -> 0
D26: =IFERROR(VLOOKUP(B26,Ingredientes!$B:$D,3,FALSE),0) -> 0 | E26: =IFERROR(VLOOKUP(B26,Ingredientes!$B:$C,2,FALSE),0) -> 0 | F26: =C26*E26 -> 0
... D30: =IFERROR(VLOOKUP(B30,Ingredientes!$B:$D,3,FALSE),0) -> 0 | E30: =IFERROR(VLOOKUP(B30,Ingredientes!$B:$C,2,FALSE),0) -> 0 | F30: =C30*E30 -> 0
F31: =SUM(F6:F30) -> 6520.044
H32: CALCULADORA DE AYUDA
B33: CONCEPTO | C33: Horas x unidad | D33: Costo por hora | E33: TOTAL | H33: MINUTOS | I33: HORAS
B34: MANO DE OBRA | D34: =MO!E18 -> 1100000 | E34: =C34*D34 -> 0 | I34: =H34/60 -> 0
B36: CONCEPTO | C36: Costos fijos por receta
B37: COSTOS FIJOS | C37: =VLOOKUP(B2,CIF!F:I,4,FALSE)

Sheet 2
B2: =MENU!B5 -> CARROT CAKE
B4: COSTO DE LOS INGREDIENTES
B5: Ingrediente | C5: Cantidad | D5: U. medida | E5: Precio unitario | F5: Total | H5: RESUMEN FINAL
B6: ACEITE DE OLIVA | C6: 0.025 | E6: =IFERROR(VLOOKUP(B6,Ingredientes!$B:$C,2,FALSE),0) -> 23500 | F6: =C6*E6 -> 587.5 | H6: Costo ingredientes: | I6: =F31 -> 10101.44
B7: ACEITE MAIZ | C7: 0.12 | E7: =IFERROR(VLOOKUP(B7,Ingredientes!$B:$C,2,FALSE),0) -> 4650 | F7: =C7*E7 -> 558 | H7: Costo laboral: | I7: 6000
B8: Azucar | C8: 0.135 | D8: =IFERROR(VLOOKUP(B8,Ingredientes!$B:$D,3,FALSE),0) -> KG | E8: =IFERROR(VLOOKUP(B8,Ingredientes!$B:$C,2,FALSE),0) -> 1132 | F8: =C8*E8 -> 152.82 | H8: Costo fijo: | I8: 5635
B9: AZUCAR MASCABO | C9: 0.45 | D9: =IFERROR(VLOOKUP(B9,Ingredientes!$B:$D,3,FALSE),0) -> 0 | E9: =IFERROR(VLOOKUP(B9,Ingredientes!$B:$C,2,FALSE),0) -> 3900 | F9: =C9*E9 -> 1755 | H9: Costo Total | I9: =SUM($I$6:$I$8) -> 21736.44
B10: Huevo | C10: 2 | D10: =IFERROR(VLOOKUP(B10,Ingredientes!$B:$D,3,FALSE),0) -> KG | E10: =IFERROR(VLOOKUP(B10,Ingredientes!$B:$C,2,FALSE),0) -> 150 | F10: =C10*E10 -> 300
B11: ZANAHORIA | C11: 0.135 | D11: =IFERROR(VLOOKUP(B11,Ingredientes!$B:$D,3,FALSE),0) -> 0 | E11: =IFERROR(VLOOKUP(B11,Ingredientes!$B:$C,2,FALSE),0) -> 800 | F11: =C11*E11 -> 108 | H11: Precio de venta | I11: 5000
B12: NUECES | C12: 0.03 | D12: =IFERROR(VLOOKUP(B12,Ingredientes!$B:$D,3,FALSE),0) -> 0 | E12: =IFERROR(VLOOKUP(B12,Ingredientes!$B:$C,2,FALSE),0) -> 22629 | F12: =C12*E12 -> 678.87 | H12: Utilidad en $ | I12: =I11-I9 -> -16736.44
B13: PASAS UVAS | C13: 0.03 | D13: =IFERROR(VLOOKUP(B13,Ingredientes!$B:$D,3,FALSE),0) -> 0 | E13: =IFERROR(VLOOKUP(B13,Ingredientes!$B:$C,2,FALSE),0) -> 4320 | F13: =C13*E13 -> 129.6 | H13: Utilidad en $ | I13: =I12/I11 -> -3.347288
B14: VICARBONATO | C14: 0.025 | D14: =IFERROR(VLOOKUP(B14,Ingredientes!$B:$D,3,FALSE),0) -> 0 | E14: =IFERROR(VLOOKUP(B14,Ingredientes!$B:$C,2,FALSE),0) -> 11000 | F14: =C14*E14 -> 275 | H14: Punto de equilibrio (u) | I14: =CIF!C67/(I11-I6-I7) -> -106.29252
B15: Harina 0000 | C15: 0.115 | D15: =IFERROR(VLOOKUP(B15,Ingredientes!$B:$D,3,FALSE),0) -> KG | E15: =IFERROR(VLOOKUP(B15,Ingredientes!$B:$C,2,FALSE),0) -> 1106 | F15: =C15*E15 -> 127.19
B16: CANELA | C16: 0.005 | D16: =IFERROR(VLOOKUP(B16,Ingredientes!$B:$D,3,FALSE),0) -> 0 | E16: =IFERROR(VLOOKUP(B16,Ingredientes!$B:$C,2,FALSE),0) -> 0 | F16: =C16*E16 -> 0
B17: POLVO DE HORNEAR | C17: 0.005 | D17: =IFERROR(VLOOKUP(B17,Ingredientes!$B:$D,3,FALSE),0) -> 0 | E17: =IFERROR(VLOOKUP(B17,Ingredientes!$B:$C,2,FALSE),0) -> 22000 | F17: =C17*E17 -> 110
B18: CHOCOLATE COBERTURA BLANCO | C18: 0.1 | D18: =IFERROR(VLOOKUP(B18,Ingredientes!$B:$D,3,FALSE),0) -> 0 | E18: =IFERROR(VLOOKUP(B18,Ingredientes!$B:$C,2,FALSE),0) -> 26864 | F18: =C18*E18 -> 2686.4
B19: QUESO CREMA | C19: 0.1 | D19: =IFERROR(VLOOKUP(B19,Ingredientes!$B:$D,3,FALSE),0) -> 0 | E19: =IFERROR(VLOOKUP(B19,Ingredientes!$B:$C,2,FALSE),0) -> 7200 | F19: =C19*E19 -> 720
B20: CREMA DE LECHE | C20: 0.2 | D20: =IFERROR(VLOOKUP(B20,Ingredientes!$B:$D,3,FALSE),0) -> 0 | E20: =IFERROR(VLOOKUP(B20,Ingredientes!$B:$C,2,FALSE),0) -> 9565.3 | F20: =C20*E20 -> 1913.06
D21: =IFERROR(VLOOKUP(B21,Ingredientes!$B:$D,3,FALSE),0) -> 0 | E21: =IFERROR(VLOOKUP(B21,Ingredientes!$B:$C,2,FALSE),0) -> 0 | F21: =C21*E21 -> 0
D22: =IFERROR(VLOOKUP(B22,Ingredientes!$B:$D,3,FALSE),0) -> 0 | E22: =IFERROR(VLOOKUP(B22,Ingredientes!$B:$C,2,FALSE),0) -> 0 | F22: =C22*E22 -> 0
D23: =IFERROR(VLOOKUP(B23,Ingredientes!$B:$D,3,FALSE),0) -> 0 | E23: =IFERROR(VLOOKUP(B23,Ingredientes!$B:$C,2,FALSE),0) -> 0 | F23: =C23*E23 -> 0
D24: =IFERROR(VLOOKUP(B24,Ingredientes!$B:$D,3,FALSE),0) -> 0 | E24: =IFERROR(VLOOKUP(B24,Ingredientes!$B:$C,2,FALSE),0) -> 0 | F24: =C24*E24 -> 0
D25: =IFERROR(VLOOKUP(B25,Ingredientes!$B:$D,3,FALSE),0) -> 0 | E25: =IFERROR(VLOOKUP(B25,Ingredientes!$B:$C,2,FALSE),0) -> 0 | F25: =C25*E25 -> 0
D26: =IFERROR(VLOOKUP(B26,Ingredientes!$B:$D,3,FALSE),0) -> 0 | E26: =IFERROR(VLOOKUP(B26,Ingredientes!$B:$C,2,FALSE),0) -> 0 | F26: =C26*E26 -> 0
D27: =IFERROR(VLOOKUP(B27,Ingredientes!$B:$D,3,FALSE),0) -> 0 | E27: =IFERROR(VLOOKUP(B27,Ingredientes!$B:$C,2,FALSE),0) -> 0 | F27: =C27*E27 -> 0
D28: =IFERROR(VLOOKUP(B28,Ingredientes!$B:$D,3,FALSE),0) -> 0 | E28: =IFERROR(VLOOKUP(B28,Ingredientes!$B:$C,2,FALSE),0) -> 0 | F28: =C28*E28 -> 0
D29: =IFERROR(VLOOKUP(B29,Ingredientes!$B:$D,3,FALSE),0) -> 0 | E29: =IFERROR(VLOOKUP(B29,Ingredientes!$B:$C,2,FALSE),0) -> 0 | F29: =C29*E29 -> 0
D30: =IFERROR(VLOOKUP(B30,Ingredientes!$B:$D,3,FALSE),0) -> 0 | E30: =IFERROR(VLOOKUP(B30,Ingredientes!$B:$C,2,FALSE),0) -> 0 | F30: =C30*E30 -> 0
F31: =SUM(F6:F30) -> 10101.44
H32: CALCULADORA DE AYUDA
B33: CONCEPTO | C33: Horas x unidad | D33: Costo por hora | E33: TOTAL | H33: MINUTOS | I33: HORAS
B34: MANO DE OBRA | D34: =MO!E18 -> 1100000 | E34: =C34*D34 -> 0 | I34: =H34/60 -> 0
B36: CONCEPTO | C36: Costos fijos por receta
B37: COSTOS FIJOS | C37: =VLOOKUP(B2,CIF!F:I,4,FALSE)

Sheet 3
B2: =MENU!B6 -> PEPAS INTEGRALES
B4: COSTO DE LOS INGREDIENTES
B5: Ingrediente | C5: Cantidad | D5: U. medida | E5: Precio unitario | F5: Total | H5: RESUMEN FINAL
B6: MANTECA | C6: 0.125 | D6: =IFERROR(VLOOKUP(B6,Ingredientes!$B:$D,3,FALSE),0) -> KG | E6: =IFERROR(VLOOKUP(B6,Ingredientes!$B:$C,2,FALSE),0) -> 10066.2 | F6: =C6*E6 -> 1258.275 | H6: Costo ingredientes: | I6: =F31 -> 4908.915
B7: AZUCAR RUBIA | C7: 0.12 | D7: =IFERROR(VLOOKUP(B7,Ingredientes!$B:$D,3,FALSE),0) -> KG | E7: =IFERROR(VLOOKUP(B7,Ingredientes!$B:$C,2,FALSE),0) -> 8847 | F7: =C7*E7 -> 1061.64 | H7: Costo laboral: | I7: 6000
B8: Huevo | C8: 1 | D8: =IFERROR(VLOOKUP(B8,Ingredientes!$B:$D,3,FALSE),0) -> KG | E8: =IFERROR(VLOOKUP(B8,Ingredientes!$B:$C,2,FALSE),0) -> 150 | F8: =C8*E8 -> 150 | H8: Costo fijo: | I8: 3820
B9: HARINA INTEGRAL | C9: 0.3 | D9: =IFERROR(VLOOKUP(B9,Ingredientes!$B:$D,3,FALSE),0) -> 0 | E9: =IFERROR(VLOOKUP(B9,Ingredientes!$B:$C,2,FALSE),0) -> 2000 | F9: =C9*E9 -> 600 | H9: Costo Total | I9: =SUM($I$6:$I$8) -> 14728.915
B10: POLVO DE HORNEAR | C10: 0.012 | D10: =IFERROR(VLOOKUP(B10,Ingredientes!$B:$D,3,FALSE),0) -> 0 | E10: =IFERROR(VLOOKUP(B10,Ingredientes!$B:$C,2,FALSE),0) -> 22000 | F10: =C10*E10 -> 264
B11: ESENCIA DE VAINILLA | D11: =IFERROR(VLOOKUP(B11,Ingredientes!$B:$D,3,FALSE),0) -> 0 | E11: =IFERROR(VLOOKUP(B11,Ingredientes!$B:$C,2,FALSE),0) -> 13700 | F11: =C11*E11 -> 0 | H11: Precio de venta | I11: 5000
B12: NARANJA 315 | C12: 1 | E12: =IFERROR(VLOOKUP(B12,Ingredientes!$B:$C,2,FALSE),0) -> 315 | F12: =C12*E12 -> 315 | H12: Utilidad en $ | I12: =I11-I9 -> -9728.915
B13: MAEMBRILLO | C13: 0.3 | D13: =IFERROR(VLOOKUP(B13,Ingredientes!$B:$D,3,FALSE),0) -> 0 | E13: =IFERROR(VLOOKUP(B13,Ingredientes!$B:$C,2,FALSE),0) -> 4200 | F13: =C13*E13 -> 1260 | H13: Utilidad en $ | I13: =I12/I11 -> -1.945783
D14: =IFERROR(VLOOKUP(B14,Ingredientes!$B:$D,3,FALSE),0) -> 0 | E14: =IFERROR(VLOOKUP(B14,Ingredientes!$B:$C,2,FALSE),0) -> 0 | F14: =C14*E14 -> 0 | H14: Punto de equilibrio (u) | I14: =CIF!C67/(I11-I6-I7) -> -199.69825
D15: =IFERROR(VLOOKUP(B15,Ingredientes!$B:$D,3,FALSE),0) -> 0 | E15: =IFERROR(VLOOKUP(B15,Ingredientes!$B:$C,2,FALSE),0) -> 0 | F15: =C15*E15 -> 0
D16: =IFERROR(VLOOKUP(B16,Ingredientes!$B:$D,3,FALSE),0) -> 0 | E16: =IFERROR(VLOOKUP(B16,Ingredientes!$B:$C,2,FALSE),0) -> 0 | F16: =C16*E16 -> 0
D17: =IFERROR(VLOOKUP(B17,Ingredientes!$B:$D,3,FALSE),0) -> 0 | E17: =IFERROR(VLOOKUP(B17,Ingredientes!$B:$C,2,FALSE),0) -> 0 | F17: =C17*E17 -> 0
D18: =IFERROR(VLOOKUP(B18,Ingredientes!$B:$D,3,FALSE),0) -> 0 | E18: =IFERROR(VLOOKUP(B18,Ingredientes!$B:$C,2,FALSE),0) -> 0 | F18: =C18*E18 -> 0
D19: =IFERROR(VLOOKUP(B19,Ingredientes!$B:$D,3,FALSE),0) -> 0 | E19: =IFERROR(VLOOKUP(B19,Ingredientes!$B:$C,2,FALSE),0) -> 0 | F19: =C19*E19 -> 0
D20: =IFERROR(VLOOKUP(B20,Ingredientes!$B:$D,3,FALSE),0) -> 0 | E20: =IFERROR(VLOOKUP(B20,Ingredientes!$B:$C,2,FALSE),0) -> 0 | F20: =C20*E20 -> 0
D21: =IFERROR(VLOOKUP(B21,Ingredientes!$B:$D,3,FALSE),0) -> 0 | E21: =IFERROR(VLOOKUP(B21,Ingredientes!$B:$C,2,FALSE),0) -> 0 | F21: =C21*E21 -> 0
D22: =IFERROR(VLOOKUP(B22,Ingredientes!$B:$D,3,FALSE),0) -> 0 | E22: =IFERROR(VLOOKUP(B22,Ingredientes!$B:$C,2,FALSE),0) -> 0 | F22: =C22*E22 -> 0
D23: =IFERROR(VLOOKUP(B23,Ingredientes!$B:$D,3,FALSE),0) -> 0 | E23: =IFERROR(VLOOKUP(B23,Ingredientes!$B:$C,2,FALSE),0) -> 0 | F23: =C23*E23 -> 0
D24: =IFERROR(VLOOKUP(B24,Ingredientes!$B:$D,3,FALSE),0) -> 0 | E24: =IFERROR(VLOOKUP(B24,Ingredientes!$B:$C,2,FALSE),0) -> 0 | F24: =C24*E24 -> 0
D25: =IFERROR(VLOOKUP(B25,Ingredientes!$B:$D,3,FALSE),0) -> 0 | E25: =IFERROR(VLOOKUP(B25,Ingredientes!$B:$C,2,FALSE),0) -> 0 | F25: =C25*E25 -> 0
D26: =IFERROR(VLOOKUP(B26,Ingredientes!$B:$D,3,FALSE),0) -> 0 | E26: =IFERROR(VLOOKUP(B26,Ingredientes!$B:$C,2,FALSE),0) -> 0 | F26: =C26*E26 -> 0
... D30: =IFERROR(VLOOKUP(B30,Ingredientes!$B:$D,3,FALSE),0) -> 0 | E30: =IFERROR(VLOOKUP(B30,Ingredientes!$B:$C,2,FALSE),0) -> 0 | F30: =C30*E30 -> 0
F31: =SUM(F6:F30) -> 4908.915
H32: CALCULADORA DE AYUDA
B33: CONCEPTO | C33: Horas x unidad | D33: Costo por hora | E33: TOTAL | H33: MINUTOS | I33: HORAS
B34: MANO DE OBRA | D34: =MO!E18 -> 1100000 | E34: =C34*D34 -> 0 | I34: =H34/60 -> 0
B36: CONCEPTO | C36: Costos fijos por receta
B37: COSTOS FIJOS | C37: =VLOOKUP(B2,CIF!F:I,4,FALSE)

Sheet 4
B2: =MENU!B7 -> Nombre de la receta 4
B4: COSTO DE LOS INGREDIENTES
B5: Ingrediente | C5: Cantidad | D5: U. medida | E5: Precio unitario | F5: Total | H5: RESUMEN FINAL
D6: =IFERROR(VLOOKUP(B6,Ingredientes!$B:$D,3,FALSE),0) -> 0 | E6: =IFERROR(VLOOKUP(B6,Ingredientes!$B:$C,2,FALSE),0) -> 0 | F6: =C6*E6 -> 0 | H6: Costo ingredientes: | I6: =F31 -> 0
D7: =IFERROR(VLOOKUP(B7,Ingredientes!$B:$D,3,FALSE),0) -> 0 | E7: =IFERROR(VLOOKUP(B7,Ingredientes!$B:$C,2,FALSE),0) -> 0 | F7: =C7*E7 -> 0 | H7: Costo laboral: | I7: =E34 -> 0
D8: =IFERROR(VLOOKUP(B8,Ingredientes!$B:$D,3,FALSE),0) -> 0 | E8: =IFERROR(VLOOKUP(B8,Ingredientes!$B:$C,2,FALSE),0) -> 0 | F8: =C8*E8 -> 0 | H8: Costo fijo: | I8: =C37
D9: =IFERROR(VLOOKUP(B9,Ingredientes!$B:$D,3,FALSE),0) -> 0 | E9: =IFERROR(VLOOKUP(B9,Ingredientes!$B:$C,2,FALSE),0) -> 0 | F9: =C9*E9 -> 0 | H9: Costo Total | I9: =SUM($I$6:$I$8) -> 0
D10: =IFERROR(VLOOKUP(B10,Ingredientes!$B:$D,3,FALSE),0) -> 0 | E10: =IFERROR(VLOOKUP(B10,Ingredientes!$B:$C,2,FALSE),0) -> 0 | F10: =C10*E10 -> 0
D11: =IFERROR(VLOOKUP(B11,Ingredientes!$B:$D,3,FALSE),0) -> 0 | E11: =IFERROR(VLOOKUP(B11,Ingredientes!$B:$C,2,FALSE),0) -> 0 | F11: =C11*E11 -> 0 | H11: Precio de venta | I11: 5000
D12: =IFERROR(VLOOKUP(B12,Ingredientes!$B:$D,3,FALSE),0) -> 0 | E12: =IFERROR(VLOOKUP(B12,Ingredientes!$B:$C,2,FALSE),0) -> 0 | F12: =C12*E12 -> 0 | H12: Utilidad en $ | I12: =I11-I9 -> 5000
D13: =IFERROR(VLOOKUP(B13,Ingredientes!$B:$D,3,FALSE),0) -> 0 | E13: =IFERROR(VLOOKUP(B13,Ingredientes!$B:$C,2,FALSE),0) -> 0 | F13: =C13*E13 -> 0 | H13: Utilidad en $ | I13: =I12/I11 -> 1
D14: =IFERROR(VLOOKUP(B14,Ingredientes!$B:$D,3,FALSE),0) -> 0 | E14: =IFERROR(VLOOKUP(B14,Ingredientes!$B:$C,2,FALSE),0) -> 0 | F14: =C14*E14 -> 0 | H14: Punto de equilibrio (u) | I14: =CIF!C67/(I11-I6-I7) -> 236
D15: =IFERROR(VLOOKUP(B15,Ingredientes!$B:$D,3,FALSE),0) -> 0 | E15: =IFERROR(VLOOKUP(B15,Ingredientes!$B:$C,2,FALSE),0) -> 0 | F15: =C15*E15 -> 0
D16: =IFERROR(VLOOKUP(B16,Ingredientes!$B:$D,3,FALSE),0) -> 0 | E16: =IFERROR(VLOOKUP(B16,Ingredientes!$B:$C,2,FALSE),0) -> 0 | F16: =C16*E16 -> 0
D17: =IFERROR(VLOOKUP(B17,Ingredientes!$B:$D,3,FALSE),0) -> 0 | E17: =IFERROR(VLOOKUP(B17,Ingredientes!$B:$C,2,FALSE),0) -> 0 | F17: =C17*E17 -> 0
D18: =IFERROR(VLOOKUP(B18,Ingredientes!$B:$D,3,FALSE),0) -> 0 | E18: =IFERROR(VLOOKUP(B18,Ingredientes!$B:$C,2,FALSE),0) -> 0 | F18: =C18*E18 -> 0
D19: =IFERROR(VLOOKUP(B19,Ingredientes!$B:$D,3,FALSE),0) -> 0 | E19: =IFERROR(VLOOKUP(B19,Ingredientes!$B:$C,2,FALSE),0) -> 0 | F19: =C19*E19 -> 0
D20: =IFERROR(VLOOKUP(B20,Ingredientes!$B:$D,3,FALSE),0) -> 0 | E20: =IFERROR(VLOOKUP(B20,Ingredientes!$B:$C,2,FALSE),0) -> 0 | F20: =C20*E20 -> 0
D21: =IFERROR(VLOOKUP(B21,Ingredientes!$B:$D,3,FALSE),0) -> 0 | E21: =IFERROR(VLOOKUP(B21,Ingredientes!$B:$C,2,FALSE),0) -> 0 | F21: =C21*E21 -> 0
D22: =IFERROR(VLOOKUP(B22,Ingredientes!$B:$D,3,FALSE),0) -> 0 | E22: =IFERROR(VLOOKUP(B22,Ingredientes!$B:$C,2,FALSE),0) -> 0 | F22: =C22*E22 -> 0
D23: =IFERROR(VLOOKUP(B23,Ingredientes!$B:$D,3,FALSE),0) -> 0 | E23: =IFERROR(VLOOKUP(B23,Ingredientes!$B:$C,2,FALSE),0) -> 0 | F23: =C23*E23 -> 0
D24: =IFERROR(VLOOKUP(B24,Ingredientes!$B:$D,3,FALSE),0) -> 0 | E24: =IFERROR(VLOOKUP(B24,Ingredientes!$B:$C,2,FALSE),0) -> 0 | F24: =C24*E24 -> 0
D25: =IFERROR(VLOOKUP(B25,Ingredientes!$B:$D,3,FALSE),0) -> 0 | E25: =IFERROR(VLOOKUP(B25,Ingredientes!$B:$C,2,FALSE),0) -> 0 | F25: =C25*E25 -> 0
D26: =IFERROR(VLOOKUP(B26,Ingredientes!$B:$D,3,FALSE),0) -> 0 | E26: =IFERROR(VLOOKUP(B26,Ingredientes!$B:$C,2,FALSE),0) -> 0 | F26: =C26*E26 -> 0
... D30: =IFERROR(VLOOKUP(B30,Ingredientes!$B:$D,3,FALSE),0) -> 0 | E30: =IFERROR(VLOOKUP(B30,Ingredientes!$B:$C,2,FALSE),0) -> 0 | F30: =C30*E30 -> 0
F31: =SUM(F6:F30) -> 0
H32: CALCULADORA DE AYUDA
B33: CONCEPTO | C33: Horas x unidad | D33: Costo por hora | E33: TOTAL | H33: MINUTOS | I33: HORAS
B34: MANO DE OBRA | D34: =MO!E18 -> 1100000 | E34: =C34*D34 -> 0 | I34: =H34/60 -> 0
B36: CONCEPTO | C36: Costos fijos por receta
B37: COSTOS FIJOS | C37: =VLOOKUP(B2,CIF!F:I,4,FALSE)

Sheet 5
B2: =MENU!B8 -> Nombre de la receta 5
B4: COSTO DE LOS INGREDIENTES
B5: Ingrediente | C5: Cantidad | D5: U. medida | E5: Precio unitario | F5: Total | H5: RESUMEN FINAL
D6: =IFERROR(VLOOKUP(B6,Ingredientes!$B:$D,3,FALSE),0) -> 0 | E6: =IFERROR(VLOOKUP(B6,Ingredientes!$B:$C,2,FALSE),0) -> 0 | F6: =C6*E6 -> 0 | H6: Costo ingredientes: | I6: =F31 -> 0
D7: =IFERROR(VLOOKUP(B7,Ingredientes!$B:$D,3,FALSE),0) -> 0 | E7: =IFERROR(VLOOKUP(B7,Ingredientes!$B:$C,2,FALSE),0) -> 0 | F7: =C7*E7 -> 0 | H7: Costo laboral: | I7: =E34 -> 0
D8: =IFERROR(VLOOKUP(B8,Ingredientes!$B:$D,3,FALSE),0) -> 0 | E8: =IFERROR(VLOOKUP(B8,Ingredientes!$B:$C,2,FALSE),0) -> 0 | F8: =C8*E8 -> 0 | H8: Costo fijo: | I8: =C37
D9: =IFERROR(VLOOKUP(B9,Ingredientes!$B:$D,3,FALSE),0) -> 0 | E9: =IFERROR(VLOOKUP(B9,Ingredientes!$B:$C,2,FALSE),0) -> 0 | F9: =C9*E9 -> 0 | H9: Costo Total | I9: =SUM($I$6:$I$8) -> 0
D10: =IFERROR(VLOOKUP(B10,Ingredientes!$B:$D,3,FALSE),0) -> 0 | E10: =IFERROR(VLOOKUP(B10,Ingredientes!$B:$C,2,FALSE),0) -> 0 | F10: =C10*E10 -> 0
D11: =IFERROR(VLOOKUP(B11,Ingredientes!$B:$D,3,FALSE),0) -> 0 | E11: =IFERROR(VLOOKUP(B11,Ingredientes!$B:$C,2,FALSE),0) -> 0 | F11: =C11*E11 -> 0 | H11: Precio de venta | I11: 5000
D12: =IFERROR(VLOOKUP(B12,Ingredientes!$B:$D,3,FALSE),0) -> 0 | E12: =IFERROR(VLOOKUP(B12,Ingredientes!$B:$C,2,FALSE),0) -> 0 | F12: =C12*E12 -> 0 | H12: Utilidad en $ | I12: =I11-I9 -> 5000
D13: =IFERROR(VLOOKUP(B13,Ingredientes!$B:$D,3,FALSE),0) -> 0 | E13: =IFERROR(VLOOKUP(B13,Ingredientes!$B:$C,2,FALSE),0) -> 0 | F13: =C13*E13 -> 0 | H13: Utilidad en $ | I13: =I12/I11 -> 1
D14: =IFERROR(VLOOKUP(B14,Ingredientes!$B:$D,3,FALSE),0) -> 0 | E14: =IFERROR(VLOOKUP(B14,Ingredientes!$B:$C,2,FALSE),0) -> 0 | F14: =C14*E14 -> 0 | H14: Punto de equilibrio (u) | I14: =CIF!C67/(I11-I6-I7) -> 236
D15: =IFERROR(VLOOKUP(B15,Ingredientes!$B:$D,3,FALSE),0) -> 0 | E15: =IFERROR(VLOOKUP(B15,Ingredientes!$B:$C,2,FALSE),0) -> 0 | F15: =C15*E15 -> 0
D16: =IFERROR(VLOOKUP(B16,Ingredientes!$B:$D,3,FALSE),0) -> 0 | E16: =IFERROR(VLOOKUP(B16,Ingredientes!$B:$C,2,FALSE),0) -> 0 | F16: =C16*E16 -> 0
D17: =IFERROR(VLOOKUP(B17,Ingredientes!$B:$D,3,FALSE),0) -> 0 | E17: =IFERROR(VLOOKUP(B17,Ingredientes!$B:$C,2,FALSE),0) -> 0 | F17: =C17*E17 -> 0
D18: =IFERROR(VLOOKUP(B18,Ingredientes!$B:$D,3,FALSE),0) -> 0 | E18: =IFERROR(VLOOKUP(B18,Ingredientes!$B:$C,2,FALSE),0) -> 0 | F18: =C18*E18 -> 0
D19: =IFERROR(VLOOKUP(B19,Ingredientes!$B:$D,3,FALSE),0) -> 0 | E19: =IFERROR(VLOOKUP(B19,Ingredientes!$B:$C,2,FALSE),0) -> 0 | F19: =C19*E19 -> 0
D20: =IFERROR(VLOOKUP(B20,Ingredientes!$B:$D,3,FALSE),0) -> 0 | E20: =IFERROR(VLOOKUP(B20,Ingredientes!$B:$C,2,FALSE),0) -> 0 | F20: =C20*E20 -> 0
D21: =IFERROR(VLOOKUP(B21,Ingredientes!$B:$D,3,FALSE),0) -> 0 | E21: =IFERROR(VLOOKUP(B21,Ingredientes!$B:$C,2,FALSE),0) -> 0 | F21: =C21*E21 -> 0
D22: =IFERROR(VLOOKUP(B22,Ingredientes!$B:$D,3,FALSE),0) -> 0 | E22: =IFERROR(VLOOKUP(B22,Ingredientes!$B:$C,2,FALSE),0) -> 0 | F22: =C22*E22 -> 0
D23: =IFERROR(VLOOKUP(B23,Ingredientes!$B:$D,3,FALSE),0) -> 0 | E23: =IFERROR(VLOOKUP(B23,Ingredientes!$B:$C,2,FALSE),0) -> 0 | F23: =C23*E23 -> 0
D24: =IFERROR(VLOOKUP(B24,Ingredientes!$B:$D,3,FALSE),0) -> 0 | E24: =IFERROR(VLOOKUP(B24,Ingredientes!$B:$C,2,FALSE),0) -> 0 | F24: =C24*E24 -> 0
D25: =IFERROR(VLOOKUP(B25,Ingredientes!$B:$D,3,FALSE),0) -> 0 | E25: =IFERROR(VLOOKUP(B25,Ingredientes!$B:$C,2,FALSE),0) -> 0 | F25: =C25*E25 -> 0
D26: =IFERROR(VLOOKUP(B26,Ingredientes!$B:$D,3,FALSE),0) -> 0 | E26: =IFERROR(VLOOKUP(B26,Ingredientes!$B:$C,2,FALSE),0) -> 0 | F26: =C26*E26 -> 0
... D30: =IFERROR(VLOOKUP(B30,Ingredientes!$B:$D,3,FALSE),0) -> 0 | E30: =IFERROR(VLOOKUP(B30,Ingredientes!$B:$C,2,FALSE),0) -> 0 | F30: =C30*E30 -> 0
F31: =SUM(F6:F30) -> 0
H32: CALCULADORA DE AYUDA
B33: CONCEPTO | C33: Horas x unidad | D33: Costo por hora | E33: TOTAL | H33: MINUTOS | I33: HORAS
B34: MANO DE OBRA | D34: =MO!E18 -> 1100000 | E34: =C34*D34 -> 0 | I34: =H34/60 -> 0
B36: CONCEPTO | C36: Costos fijos por receta
B37: COSTOS FIJOS | C37: =VLOOKUP(B2,CIF!F:I,4,FALSE)

Sheet 6
B2: =MENU!B9 -> Nombre de la receta 6
B4: COSTO DE LOS INGREDIENTES
B5: Ingrediente | C5: Cantidad | D5: U. medida | E5: Precio unitario | F5: Total | H5: RESUMEN FINAL
D6: =IFERROR(VLOOKUP(B6,Ingredientes!$B:$D,3,FALSE),0) -> 0 | E6: =IFERROR(VLOOKUP(B6,Ingredientes!$B:$C,2,FALSE),0) -> 0 | F6: =C6*E6 -> 0 | H6: Costo ingredientes: | I6: =F31 -> 0
D7: =IFERROR(VLOOKUP(B7,Ingredientes!$B:$D,3,FALSE),0) -> 0 | E7: =IFERROR(VLOOKUP(B7,Ingredientes!$B:$C,2,FALSE),0) -> 0 | F7: =C7*E7 -> 0 | H7: Costo laboral: | I7: =E34 -> 0
D8: =IFERROR(VLOOKUP(B8,Ingredientes!$B:$D,3,FALSE),0) -> 0 | E8: =IFERROR(VLOOKUP(B8,Ingredientes!$B:$C,2,FALSE),0) -> 0 | F8: =C8*E8 -> 0 | H8: Costo fijo: | I8: =C37
D9: =IFERROR(VLOOKUP(B9,Ingredientes!$B:$D,3,FALSE),0) -> 0 | E9: =IFERROR(VLOOKUP(B9,Ingredientes!$B:$C,2,FALSE),0) -> 0 | F9: =C9*E9 -> 0 | H9: Costo Total | I9: =SUM($I$6:$I$8) -> 0
D10: =IFERROR(VLOOKUP(B10,Ingredientes!$B:$D,3,FALSE),0) -> 0 | E10: =IFERROR(VLOOKUP(B10,Ingredientes!$B:$C,2,FALSE),0) -> 0 | F10: =C10*E10 -> 0
D11: =IFERROR(VLOOKUP(B11,Ingredientes!$B:$D,3,FALSE),0) -> 0 | E11: =IFERROR(VLOOKUP(B11,Ingredientes!$B:$C,2,FALSE),0) -> 0 | F11: =C11*E11 -> 0 | H11: Precio de venta | I11: 5000
D12: =IFERROR(VLOOKUP(B12,Ingredientes!$B:$D,3,FALSE),0) -> 0 | E12: =IFERROR(VLOOKUP(B12,Ingredientes!$B:$C,2,FALSE),0) -> 0 | F12: =C12*E12 -> 0 | H12: Utilidad en $ | I12: =I11-I9 -> 5000
D13: =IFERROR(VLOOKUP(B13,Ingredientes!$B:$D,3,FALSE),0) -> 0 | E13: =IFERROR(VLOOKUP(B13,Ingredientes!$B:$C,2,FALSE),0) -> 0 | F13: =C13*E13 -> 0 | H13: Utilidad en $ | I13: =I12/I11 -> 1
D14: =IFERROR(VLOOKUP(B14,Ingredientes!$B:$D,3,FALSE),0) -> 0 | E14: =IFERROR(VLOOKUP(B14,Ingredientes!$B:$C,2,FALSE),0) -> 0 | F14: =C14*E14 -> 0 | H14: Punto de equilibrio (u) | I14: =CIF!C67/(I11-I6-I7) -> 236
D15: =IFERROR(VLOOKUP(B15,Ingredientes!$B:$D,3,FALSE),0) -> 0 | E15: =IFERROR(VLOOKUP(B15,Ingredientes!$B:$C,2,FALSE),0) -> 0 | F15: =C15*E15 -> 0
D16: =IFERROR(VLOOKUP(B16,Ingredientes!$B:$D,3,FALSE),0) -> 0 | E16: =IFERROR(VLOOKUP(B16,Ingredientes!$B:$C,2,FALSE),0) -> 0 | F16: =C16*E16 -> 0
D17: =IFERROR(VLOOKUP(B17,Ingredientes!$B:$D,3,FALSE),0) -> 0 | E17: =IFERROR(VLOOKUP(B17,Ingredientes!$B:$C,2,FALSE),0) -> 0 | F17: =C17*E17 -> 0
D18: =IFERROR(VLOOKUP(B18,Ingredientes!$B:$D,3,FALSE),0) -> 0 | E18: =IFERROR(VLOOKUP(B18,Ingredientes!$B:$C,2,FALSE),0) -> 0 | F18: =C18*E18 -> 0
D19: =IFERROR(VLOOKUP(B19,Ingredientes!$B:$D,3,FALSE),0) -> 0 | E19: =IFERROR(VLOOKUP(B19,Ingredientes!$B:$C,2,FALSE),0) -> 0 | F19: =C19*E19 -> 0
D20: =IFERROR(VLOOKUP(B20,Ingredientes!$B:$D,3,FALSE),0) -> 0 | E20: =IFERROR(VLOOKUP(B20,Ingredientes!$B:$C,2,FALSE),0) -> 0 | F20: =C20*E20 -> 0
D21: =IFERROR(VLOOKUP(B21,Ingredientes!$B:$D,3,FALSE),0) -> 0 | E21: =IFERROR(VLOOKUP(B21,Ingredientes!$B:$C,2,FALSE),0) -> 0 | F21: =C21*E21 -> 0
D22: =IFERROR(VLOOKUP(B22,Ingredientes!$B:$D,3,FALSE),0) -> 0 | E22: =IFERROR(VLOOKUP(B22,Ingredientes!$B:$C,2,FALSE),0) -> 0 | F22: =C22*E22 -> 0
D23: =IFERROR(VLOOKUP(B23,Ingredientes!$B:$D,3,FALSE),0) -> 0 | E23: =IFERROR(VLOOKUP(B23,Ingredientes!$B:$C,2,FALSE),0) -> 0 | F23: =C23*E23 -> 0
D24: =IFERROR(VLOOKUP(B24,Ingredientes!$B:$D,3,FALSE),0) -> 0 | E24: =IFERROR(VLOOKUP(B24,Ingredientes!$B:$C,2,FALSE),0) -> 0 | F24: =C24*E24 -> 0
D25: =IFERROR(VLOOKUP(B25,Ingredientes!$B:$D,3,FALSE),0) -> 0 | E25: =IFERROR(VLOOKUP(B25,Ingredientes!$B:$C,2,FALSE),0) -> 0 | F25: =C25*E25 -> 0
D26: =IFERROR(VLOOKUP(B26,Ingredientes!$B:$D,3,FALSE),0) -> 0 | E26: =IFERROR(VLOOKUP(B26,Ingredientes!$B:$C,2,FALSE),0) -> 0 | F26: =C26*E26 -> 0
... D30: =IFERROR(VLOOKUP(B30,Ingredientes!$B:$D,3,FALSE),0) -> 0 | E30: =IFERROR(VLOOKUP(B30,Ingredientes!$B:$C,2,FALSE),0) -> 0 | F30: =C30*E30 -> 0
F31: =SUM(F6:F30) -> 0
H32: CALCULADORA DE AYUDA
B33: CONCEPTO | C33: Horas x unidad | D33: Costo por hora | E33: TOTAL | H33: MINUTOS | I33: HORAS
B34: MANO DE OBRA | D34: =MO!E18 -> 1100000 | E34: =C34*D34 -> 0 | I34: =H34/60 -> 0
B36: CONCEPTO | C36: Costos fijos por receta
B37: COSTOS FIJOS | C37: =VLOOKUP(B2,CIF!F:I,4,FALSE)

Sheet 7
B2: =MENU!B10 -> Nombre de la receta 7
B4: COSTO DE LOS INGREDIENTES
B5: Ingrediente | C5: Cantidad | D5: U. medida | E5: Precio unitario | F5: Total | H5: RESUMEN FINAL
D6: =IFERROR(VLOOKUP(B6,Ingredientes!$B:$D,3,FALSE),0) -> 0 | E6: =IFERROR(VLOOKUP(B6,Ingredientes!$B:$C,2,FALSE),0) -> 0 | F6: =C6*E6 -> 0 | H6: Costo ingredientes: | I6: =F31 -> 0
D7: =IFERROR(VLOOKUP(B7,Ingredientes!$B:$D,3,FALSE),0) -> 0 | E7: =IFERROR(VLOOKUP(B7,Ingredientes!$B:$C,2,FALSE),0) -> 0 | F7: =C7*E7 -> 0 | H7: Costo laboral: | I7: =E34 -> 0
D8: =IFERROR(VLOOKUP(B8,Ingredientes!$B:$D,3,FALSE),0) -> 0 | E8: =IFERROR(VLOOKUP(B8,Ingredientes!$B:$C,2,FALSE),0) -> 0 | F8: =C8*E8 -> 0 | H8: Costo fijo: | I8: =C37
D9: =IFERROR(VLOOKUP(B9,Ingredientes!$B:$D,3,FALSE),0) -> 0 | E9: =IFERROR(VLOOKUP(B9,Ingredientes!$B:$C,2,FALSE),0) -> 0 | F9: =C9*E9 -> 0 | H9: Costo Total | I9: =SUM($I$6:$I$8) -> 0
D10: =IFERROR(VLOOKUP(B10,Ingredientes!$B:$D,3,FALSE),0) -> 0 | E10: =IFERROR(VLOOKUP(B10,Ingredientes!$B:$C,2,FALSE),0) -> 0 | F10: =C10*E10 -> 0
D11: =IFERROR(VLOOKUP(B11,Ingredientes!$B:$D,3,FALSE),0) -> 0 | E11: =IFERROR(VLOOKUP(B11,Ingredientes!$B:$C,2,FALSE),0) -> 0 | F11: =C11*E11 -> 0 | H11: Precio de venta | I11: 5000
D12: =IFERROR(VLOOKUP(B12,Ingredientes!$B:$D,3,FALSE),0) -> 0 | E12: =IFERROR(VLOOKUP(B12,Ingredientes!$B:$C,2,FALSE),0) -> 0 | F12: =C12*E12 -> 0 | H12: Utilidad en $ | I12: =I11-I9 -> 5000
D13: =IFERROR(VLOOKUP(B13,Ingredientes!$B:$D,3,FALSE),0) -> 0 | E13: =IFERROR(VLOOKUP(B13,Ingredientes!$B:$C,2,FALSE),0) -> 0 | F13: =C13*E13 -> 0 | H13: Utilidad en $ | I13: =I12/I11 -> 1
D14: =IFERROR(VLOOKUP(B14,Ingredientes!$B:$D,3,FALSE),0) -> 0 | E14: =IFERROR(VLOOKUP(B14,Ingredientes!$B:$C,2,FALSE),0) -> 0 | F14: =C14*E14 -> 0 | H14: Punto de equilibrio (u) | I14: =CIF!C67/(I11-I6-I7) -> 236
D15: =IFERROR(VLOOKUP(B15,Ingredientes!$B:$D,3,FALSE),0) -> 0 | E15: =IFERROR(VLOOKUP(B15,Ingredientes!$B:$C,2,FALSE),0) -> 0 | F15: =C15*E15 -> 0
D16: =IFERROR(VLOOKUP(B16,Ingredientes!$B:$D,3,FALSE),0) -> 0 | E16: =IFERROR(VLOOKUP(B16,Ingredientes!$B:$C,2,FALSE),0) -> 0 | F16: =C16*E16 -> 0
D17: =IFERROR(VLOOKUP(B17,Ingredientes!$B:$D,3,FALSE),0) -> 0 | E17: =IFERROR(VLOOKUP(B17,Ingredientes!$B:$C,2,FALSE),0) -> 0 | F17: =C17*E17 -> 0
D18: =IFERROR(VLOOKUP(B18,Ingredientes!$B:$D,3,FALSE),0) -> 0 | E18: =IFERROR(VLOOKUP(B18,Ingredientes!$B:$C,2,FALSE),0) -> 0 | F18: =C18*E18 -> 0
D19: =IFERROR(VLOOKUP(B19,Ingredientes!$B:$D,3,FALSE),0) -> 0 | E19: =IFERROR(VLOOKUP(B19,Ingredientes!$B:$C,2,FALSE),0) -> 0 | F19: =C19*E19 -> 0
D20: =IFERROR(VLOOKUP(B20,Ingredientes!$B:$D,3,FALSE),0) -> 0 | E20: =IFERROR(VLOOKUP(B20,Ingredientes!$B:$C,2,FALSE),0) -> 0 | F20: =C20*E20 -> 0
D21: =IFERROR(VLOOKUP(B21,Ingredientes!$B:$D,3,FALSE),0) -> 0 | E21: =IFERROR(VLOOKUP(B21,Ingredientes!$B:$C,2,FALSE),0) -> 0 | F21: =C21*E21 -> 0
D22: =IFERROR(VLOOKUP(B22,Ingredientes!$B:$D,3,FALSE),0) -> 0 | E22: =IFERROR(VLOOKUP(B22,Ingredientes!$B:$C,2,FALSE),0) -> 0 | F22: =C22*E22 -> 0
D23: =IFERROR(VLOOKUP(B23,Ingredientes!$B:$D,3,FALSE),0) -> 0 | E23: =IFERROR(VLOOKUP(B23,Ingredientes!$B:$C,2,FALSE),0) -> 0 | F23: =C23*E23 -> 0
D24: =IFERROR(VLOOKUP(B24,Ingredientes!$B:$D,3,FALSE),0) -> 0 | E24: =IFERROR(VLOOKUP(B24,Ingredientes!$B:$C,2,FALSE),0) -> 0 | F24: =C24*E24 -> 0
D25: =IFERROR(VLOOKUP(B25,Ingredientes!$B:$D,3,FALSE),0) -> 0 | E25: =IFERROR(VLOOKUP(B25,Ingredientes!$B:$C,2,FALSE),0) -> 0 | F25: =C25*E25 -> 0
D26: =IFERROR(VLOOKUP(B26,Ingredientes!$B:$D,3,FALSE),0) -> 0 | E26: =IFERROR(VLOOKUP(B26,Ingredientes!$B:$C,2,FALSE),0) -> 0 | F26: =C26*E26 -> 0
... D30: =IFERROR(VLOOKUP(B30,Ingredientes!$B:$D,3,FALSE),0) -> 0 | E30: =IFERROR(VLOOKUP(B30,Ingredientes!$B:$C,2,FALSE),0) -> 0 | F30: =C30*E30 -> 0
F31: =SUM(F6:F30) -> 0
H32: CALCULADORA DE AYUDA
B33: CONCEPTO | C33: Horas x unidad | D33: Costo por hora | E33: TOTAL | H33: MINUTOS | I33: HORAS
B34: MANO DE OBRA | D34: =MO!E18 -> 1100000 | E34: =C34*D34 -> 0 | I34: =H34/60 -> 0
B36: CONCEPTO | C36: Costos fijos por receta
B37: COSTOS FIJOS | C37: =VLOOKUP(B2,CIF!F:I,4,FALSE)

Sheet 8
B2: =MENU!B11 -> Nombre de la receta 8
B4: COSTO DE LOS INGREDIENTES
B5: Ingrediente | C5: Cantidad | D5: U. medida | E5: Precio unitario | F5: Total | H5: RESUMEN FINAL
D6: =IFERROR(VLOOKUP(B6,Ingredientes!$B:$D,3,FALSE),0) -> 0 | E6: =IFERROR(VLOOKUP(B6,Ingredientes!$B:$C,2,FALSE),0) -> 0 | F6: =C6*E6 -> 0 | H6: Costo ingredientes: | I6: =F31 -> 0
D7: =IFERROR(VLOOKUP(B7,Ingredientes!$B:$D,3,FALSE),0) -> 0 | E7: =IFERROR(VLOOKUP(B7,Ingredientes!$B:$C,2,FALSE),0) -> 0 | F7: =C7*E7 -> 0 | H7: Costo laboral: | I7: =E34 -> 0
D8: =IFERROR(VLOOKUP(B8,Ingredientes!$B:$D,3,FALSE),0) -> 0 | E8: =IFERROR(VLOOKUP(B8,Ingredientes!$B:$C,2,FALSE),0) -> 0 | F8: =C8*E8 -> 0 | H8: Costo fijo: | I8: =C37
D9: =IFERROR(VLOOKUP(B9,Ingredientes!$B:$D,3,FALSE),0) -> 0 | E9: =IFERROR(VLOOKUP(B9,Ingredientes!$B:$C,2,FALSE),0) -> 0 | F9: =C9*E9 -> 0 | H9: Costo Total | I9: =SUM($I$6:$I$8) -> 0
D10: =IFERROR(VLOOKUP(B10,Ingredientes!$B:$D,3,FALSE),0) -> 0 | E10: =IFERROR(VLOOKUP(B10,Ingredientes!$B:$C,2,FALSE),0) -> 0 | F10: =C10*E10 -> 0
D11: =IFERROR(VLOOKUP(B11,Ingredientes!$B:$D,3,FALSE),0) -> 0 | E11: =IFERROR(VLOOKUP(B11,Ingredientes!$B:$C,2,FALSE),0) -> 0 | F11: =C11*E11 -> 0 | H11: Precio de venta | I11: 5000
D12: =IFERROR(VLOOKUP(B12,Ingredientes!$B:$D,3,FALSE),0) -> 0 | E12: =IFERROR(VLOOKUP(B12,Ingredientes!$B:$C,2,FALSE),0) -> 0 | F12: =C12*E12 -> 0 | H12: Utilidad en $ | I12: =I11-I9 -> 5000
D13: =IFERROR(VLOOKUP(B13,Ingredientes!$B:$D,3,FALSE),0) -> 0 | E13: =IFERROR(VLOOKUP(B13,Ingredientes!$B:$C,2,FALSE),0) -> 0 | F13: =C13*E13 -> 0 | H13: Utilidad en $ | I13: =I12/I11 -> 1
D14: =IFERROR(VLOOKUP(B14,Ingredientes!$B:$D,3,FALSE),0) -> 0 | E14: =IFERROR(VLOOKUP(B14,Ingredientes!$B:$C,2,FALSE),0) -> 0 | F14: =C14*E14 -> 0 | H14: Punto de equilibrio (u) | I14: =CIF!C67/(I11-I6-I7) -> 236
D15: =IFERROR(VLOOKUP(B15,Ingredientes!$B:$D,3,FALSE),0) -> 0 | E15: =IFERROR(VLOOKUP(B15,Ingredientes!$B:$C,2,FALSE),0) -> 0 | F15: =C15*E15 -> 0
D16: =IFERROR(VLOOKUP(B16,Ingredientes!$B:$D,3,FALSE),0) -> 0 | E16: =IFERROR(VLOOKUP(B16,Ingredientes!$B:$C,2,FALSE),0) -> 0 | F16: =C16*E16 -> 0
D17: =IFERROR(VLOOKUP(B17,Ingredientes!$B:$D,3,FALSE),0) -> 0 | E17: =IFERROR(VLOOKUP(B17,Ingredientes!$B:$C,2,FALSE),0) -> 0 | F17: =C17*E17 -> 0
D18: =IFERROR(VLOOKUP(B18,Ingredientes!$B:$D,3,FALSE),0) -> 0 | E18: =IFERROR(VLOOKUP(B18,Ingredientes!$B:$C,2,FALSE),0) -> 0 | F18: =C18*E18 -> 0
D19: =IFERROR(VLOOKUP(B19,Ingredientes!$B:$D,3,FALSE),0) -> 0 | E19: =IFERROR(VLOOKUP(B19,Ingredientes!$B:$C,2,FALSE),0) -> 0 | F19: =C19*E19 -> 0
D20: =IFERROR(VLOOKUP(B20,Ingredientes!$B:$D,3,FALSE),0) -> 0 | E20: =IFERROR(VLOOKUP(B20,Ingredientes!$B:$C,2,FALSE),0) -> 0 | F20: =C20*E20 -> 0
D21: =IFERROR(VLOOKUP(B21,Ingredientes!$B:$D,3,FALSE),0) -> 0 | E21: =IFERROR(VLOOKUP(B21,Ingredientes!$B:$C,2,FALSE),0) -> 0 | F21: =C21*E21 -> 0
D22: =IFERROR(VLOOKUP(B22,Ingredientes!$B:$D,3,FALSE),0) -> 0 | E22: =IFERROR(VLOOKUP(B22,Ingredientes!$B:$C,2,FALSE),0) -> 0 | F22: =C22*E22 -> 0
D23: =IFERROR(VLOOKUP(B23,Ingredientes!$B:$D,3,FALSE),0) -> 0 | E23: =IFERROR(VLOOKUP(B23,Ingredientes!$B:$C,2,FALSE),0) -> 0 | F23: =C23*E23 -> 0
D24: =IFERROR(VLOOKUP(B24,Ingredientes!$B:$D,3,FALSE),0) -> 0 | E24: =IFERROR(VLOOKUP(B24,Ingredientes!$B:$C,2,FALSE),0) -> 0 | F24: =C24*E24 -> 0
D25: =IFERROR(VLOOKUP(B25,Ingredientes!$B:$D,3,FALSE),0) -> 0 | E25: =IFERROR(VLOOKUP(B25,Ingredientes!$B:$C,2,FALSE),0) -> 0 | F25: =C25*E25 -> 0
D26: =IFERROR(VLOOKUP(B26,Ingredientes!$B:$D,3,FALSE),0) -> 0 | E26: =IFERROR(VLOOKUP(B26,Ingredientes!$B:$C,2,FALSE),0) -> 0 | F26: =C26*E26 -> 0
... D30: =IFERROR(VLOOKUP(B30,Ingredientes!$B:$D,3,FALSE),0) -> 0 | E30: =IFERROR(VLOOKUP(B30,Ingredientes!$B:$C,2,FALSE),0) -> 0 | F30: =C30*E30 -> 0
F31: =SUM(F6:F30) -> 0
H32: CALCULADORA DE AYUDA
B33: CONCEPTO | C33: Horas x unidad | D33: Costo por hora | E33: TOTAL | H33: MINUTOS | I33: HORAS
B34: MANO DE OBRA | D34: =MO!E18 -> 1100000 | E34: =C34*D34 -> 0 | I34: =H34/60 -> 0
B36: CONCEPTO | C36: Costos fijos por receta
B37: COSTOS FIJOS | C37: =VLOOKUP(B2,CIF!F:I,4,FALSE)

Sheet 9
B2: =MENU!B12 -> Nombre de la receta 9
B4: COSTO DE LOS INGREDIENTES
B5: Ingrediente | C5: Cantidad | D5: U. medida | E5: Precio unitario | F5: Total | H5: RESUMEN FINAL
D6: =IFERROR(VLOOKUP(B6,Ingredientes!$B:$D,3,FALSE),0) -> 0 | E6: =IFERROR(VLOOKUP(B6,Ingredientes!$B:$C,2,FALSE),0) -> 0 | F6: =C6*E6 -> 0 | H6: Costo ingredientes: | I6: =F31 -> 0
D7: =IFERROR(VLOOKUP(B7,Ingredientes!$B:$D,3,FALSE),0) -> 0 | E7: =IFERROR(VLOOKUP(B7,Ingredientes!$B:$C,2,FALSE),0) -> 0 | F7: =C7*E7 -> 0 | H7: Costo laboral: | I7: =E34 -> 0
D8: =IFERROR(VLOOKUP(B8,Ingredientes!$B:$D,3,FALSE),0) -> 0 | E8: =IFERROR(VLOOKUP(B8,Ingredientes!$B:$C,2,FALSE),0) -> 0 | F8: =C8*E8 -> 0 | H8: Costo fijo: | I8: =C37
D9: =IFERROR(VLOOKUP(B9,Ingredientes!$B:$D,3,FALSE),0) -> 0 | E9: =IFERROR(VLOOKUP(B9,Ingredientes!$B:$C,2,FALSE),0) -> 0 | F9: =C9*E9 -> 0 | H9: Costo Total | I9: =SUM($I$6:$I$8) -> 0
D10: =IFERROR(VLOOKUP(B10,Ingredientes!$B:$D,3,FALSE),0) -> 0 | E10: =IFERROR(VLOOKUP(B10,Ingredientes!$B:$C,2,FALSE),0) -> 0 | F10: =C10*E10 -> 0
D11: =IFERROR(VLOOKUP(B11,Ingredientes!$B:$D,3,FALSE),0) -> 0 | E11: =IFERROR(VLOOKUP(B11,Ingredientes!$B:$C,2,FALSE),0) -> 0 | F11: =C11*E11 -> 0 | H11: Precio de venta | I11: 5000
D12: =IFERROR(VLOOKUP(B12,Ingredientes!$B:$D,3,FALSE),0) -> 0 | E12: =IFERROR(VLOOKUP(B12,Ingredientes!$B:$C,2,FALSE),0) -> 0 | F12: =C12*E12 -> 0 | H12: Utilidad en $ | I12: =I11-I9 -> 5000
D13: =IFERROR(VLOOKUP(B13,Ingredientes!$B:$D,3,FALSE),0) -> 0 | E13: =IFERROR(VLOOKUP(B13,Ingredientes!$B:$C,2,FALSE),0) -> 0 | F13: =C13*E13 -> 0 | H13: Utilidad en $ | I13: =I12/I11 -> 1
D14: =IFERROR(VLOOKUP(B14,Ingredientes!$B:$D,3,FALSE),0) -> 0 | E14: =IFERROR(VLOOKUP(B14,Ingredientes!$B:$C,2,FALSE),0) -> 0 | F14: =C14*E14 -> 0 | H14: Punto de equilibrio (u) | I14: =CIF!C67/(I11-I6-I7) -> 236
D15: =IFERROR(VLOOKUP(B15,Ingredientes!$B:$D,3,FALSE),0) -> 0 | E15: =IFERROR(VLOOKUP(B15,Ingredientes!$B:$C,2,FALSE),0) -> 0 | F15: =C15*E15 -> 0
D16: =IFERROR(VLOOKUP(B16,Ingredientes!$B:$D,3,FALSE),0) -> 0 | E16: =IFERROR(VLOOKUP(B16,Ingredientes!$B:$C,2,FALSE),0) -> 0 | F16: =C16*E16 -> 0
D17: =IFERROR(VLOOKUP(B17,Ingredientes!$B:$D,3,FALSE),0) -> 0 | E17: =IFERROR(VLOOKUP(B17,Ingredientes!$B:$C,2,FALSE),0) -> 0 | F17: =C17*E17 -> 0
D18: =IFERROR(VLOOKUP(B18,Ingredientes!$B:$D,3,FALSE),0) -> 0 | E18: =IFERROR(VLOOKUP(B18,Ingredientes!$B:$C,2,FALSE),0) -> 0 | F18: =C18*E18 -> 0
D19: =IFERROR(VLOOKUP(B19,Ingredientes!$B:$D,3,FALSE),0) -> 0 | E19: =IFERROR(VLOOKUP(B19,Ingredientes!$B:$C,2,FALSE),0) -> 0 | F19: =C19*E19 -> 0
D20: =IFERROR(VLOOKUP(B20,Ingredientes!$B:$D,3,FALSE),0) -> 0 | E20: =IFERROR(VLOOKUP(B20,Ingredientes!$B:$C,2,FALSE),0) -> 0 | F20: =C20*E20 -> 0
D21: =IFERROR(VLOOKUP(B21,Ingredientes!$B:$D,3,FALSE),0) -> 0 | E21: =IFERROR(VLOOKUP(B21,Ingredientes!$B:$C,2,FALSE),0) -> 0 | F21: =C21*E21 -> 0
D22: =IFERROR(VLOOKUP(B22,Ingredientes!$B:$D,3,FALSE),0) -> 0 | E22: =IFERROR(VLOOKUP(B22,Ingredientes!$B:$C,2,FALSE),0) -> 0 | F22: =C22*E22 -> 0
D23: =IFERROR(VLOOKUP(B23,Ingredientes!$B:$D,3,FALSE),0) -> 0 | E23: =IFERROR(VLOOKUP(B23,Ingredientes!$B:$C,2,FALSE),0) -> 0 | F23: =C23*E23 -> 0
D24: =IFERROR(VLOOKUP(B24,Ingredientes!$B:$D,3,FALSE),0) -> 0 | E24: =IFERROR(VLOOKUP(B24,Ingredientes!$B:$C,2,FALSE),0) -> 0 | F24: =C24*E24 -> 0
D25: =IFERROR(VLOOKUP(B25,Ingredientes!$B:$D,3,FALSE),0) -> 0 | E25: =IFERROR(VLOOKUP(B25,Ingredientes!$B:$C,2,FALSE),0) -> 0 | F25: =C25*E25 -> 0
D26: =IFERROR(VLOOKUP(B26,Ingredientes!$B:$D,3,FALSE),0) -> 0 | E26: =IFERROR(VLOOKUP(B26,Ingredientes!$B:$C,2,FALSE),0) -> 0 | F26: =C26*E26 -> 0
... D30: =IFERROR(VLOOKUP(B30,Ingredientes!$B:$D,3,FALSE),0) -> 0 | E30: =IFERROR(VLOOKUP(B30,Ingredientes!$B:$C,2,FALSE),0) -> 0 | F30: =C30*E30 -> 0
F31: =SUM(F6:F30) -> 0
H32: CALCULADORA DE AYUDA
B33: CONCEPTO | C33: Horas x unidad | D33: Costo por hora | E33: TOTAL | H33: MINUTOS | I33: HORAS
B34: MANO DE OBRA | D34: =MO!E18 -> 1100000 | E34: =C34*D34 -> 0 | I34: =H34/60 -> 0
B36: CONCEPTO | C36: Costos fijos por receta
B37: COSTOS FIJOS | C37: =VLOOKUP(B2,CIF!F:I,4,FALSE)

Sheet 10
B2: =MENU!B13 -> Nombre de la receta 10
B4: COSTO DE LOS INGREDIENTES
B5: Ingrediente | C5: Cantidad | D5: U. medida | E5: Precio unitario | F5: Total | H5: RESUMEN FINAL
D6: =IFERROR(VLOOKUP(B6,Ingredientes!$B:$D,3,FALSE),0) -> 0 | E6: =IFERROR(VLOOKUP(B6,Ingredientes!$B:$C,2,FALSE),0) -> 0 | F6: =C6*E6 -> 0 | H6: Costo ingredientes: | I6: =F31 -> 0
D7: =IFERROR(VLOOKUP(B7,Ingredientes!$B:$D,3,FALSE),0) -> 0 | E7: =IFERROR(VLOOKUP(B7,Ingredientes!$B:$C,2,FALSE),0) -> 0 | F7: =C7*E7 -> 0 | H7: Costo laboral: | I7: =E34 -> 0
D8: =IFERROR(VLOOKUP(B8,Ingredientes!$B:$D,3,FALSE),0) -> 0 | E8: =IFERROR(VLOOKUP(B8,Ingredientes!$B:$C,2,FALSE),0) -> 0 | F8: =C8*E8 -> 0 | H8: Costo fijo: | I8: =C37
D9: =IFERROR(VLOOKUP(B9,Ingredientes!$B:$D,3,FALSE),0) -> 0 | E9: =IFERROR(VLOOKUP(B9,Ingredientes!$B:$C,2,FALSE),0) -> 0 | F9: =C9*E9 -> 0 | H9: Costo Total | I9: =SUM($I$6:$I$8) -> 0
D10: =IFERROR(VLOOKUP(B10,Ingredientes!$B:$D,3,FALSE),0) -> 0 | E10: =IFERROR(VLOOKUP(B10,Ingredientes!$B:$C,2,FALSE),0) -> 0 | F10: =C10*E10 -> 0
D11: =IFERROR(VLOOKUP(B11,Ingredientes!$B:$D,3,FALSE),0) -> 0 | E11: =IFERROR(VLOOKUP(B11,Ingredientes!$B:$C,2,FALSE),0) -> 0 | F11: =C11*E11 -> 0 | H11: Precio de venta | I11: 5000
D12: =IFERROR(VLOOKUP(B12,Ingredientes!$B:$D,3,FALSE),0) -> 0 | E12: =IFERROR(VLOOKUP(B12,Ingredientes!$B:$C,2,FALSE),0) -> 0 | F12: =C12*E12 -> 0 | H12: Utilidad en $ | I12: =I11-I9 -> 5000
D13: =IFERROR(VLOOKUP(B13,Ingredientes!$B:$D,3,FALSE),0) -> 0 | E13: =IFERROR(VLOOKUP(B13,Ingredientes!$B:$C,2,FALSE),0) -> 0 | F13: =C13*E13 -> 0 | H13: Utilidad en $ | I13: =I12/I11 -> 1
D14: =IFERROR(VLOOKUP(B14,Ingredientes!$B:$D,3,FALSE),0) -> 0 | E14: =IFERROR(VLOOKUP(B14,Ingredientes!$B:$C,2,FALSE),0) -> 0 | F14: =C14*E14 -> 0 | H14: Punto de equilibrio (u) | I14: =CIF!C67/(I11-I6-I7) -> 236
D15: =IFERROR(VLOOKUP(B15,Ingredientes!$B:$D,3,FALSE),0) -> 0 | E15: =IFERROR(VLOOKUP(B15,Ingredientes!$B:$C,2,FALSE),0) -> 0 | F15: =C15*E15 -> 0
D16: =IFERROR(VLOOKUP(B16,Ingredientes!$B:$D,3,FALSE),0) -> 0 | E16: =IFERROR(VLOOKUP(B16,Ingredientes!$B:$C,2,FALSE),0) -> 0 | F16: =C16*E16 -> 0
D17: =IFERROR(VLOOKUP(B17,Ingredientes!$B:$D,3,FALSE),0) -> 0 | E17: =IFERROR(VLOOKUP(B17,Ingredientes!$B:$C,2,FALSE),0) -> 0 | F17: =C17*E17 -> 0
D18: =IFERROR(VLOOKUP(B18,Ingredientes!$B:$D,3,FALSE),0) -> 0 | E18: =IFERROR(VLOOKUP(B18,Ingredientes!$B:$C,2,FALSE),0) -> 0 | F18: =C18*E18 -> 0
D19: =IFERROR(VLOOKUP(B19,Ingredientes!$B:$D,3,FALSE),0) -> 0 | E19: =IFERROR(VLOOKUP(B19,Ingredientes!$B:$C,2,FALSE),0) -> 0 | F19: =C19*E19 -> 0
D20: =IFERROR(VLOOKUP(B20,Ingredientes!$B:$D,3,FALSE),0) -> 0 | E20: =IFERROR(VLOOKUP(B20,Ingredientes!$B:$C,2,FALSE),0) -> 0 | F20: =C20*E20 -> 0
D21: =IFERROR(VLOOKUP(B21,Ingredientes!$B:$D,3,FALSE),0) -> 0 | E21: =IFERROR(VLOOKUP(B21,Ingredientes!$B:$C,2,FALSE),0) -> 0 | F21: =C21*E21 -> 0
D22: =IFERROR(VLOOKUP(B22,Ingredientes!$B:$D,3,FALSE),0) -> 0 | E22: =IFERROR(VLOOKUP(B22,Ingredientes!$B:$C,2,FALSE),0) -> 0 | F22: =C22*E22 -> 0
D23: =IFERROR(VLOOKUP(B23,Ingredientes!$B:$D,3,FALSE),0) -> 0 | E23: =IFERROR(VLOOKUP(B23,Ingredientes!$B:$C,2,FALSE),0) -> 0 | F23: =C23*E23 -> 0
D24: =IFERROR(VLOOKUP(B24,Ingredientes!$B:$D,3,FALSE),0) -> 0 | E24: =IFERROR(VLOOKUP(B24,Ingredientes!$B:$C,2,FALSE),0) -> 0 | F24: =C24*E24 -> 0
D25: =IFERROR(VLOOKUP(B25,Ingredientes!$B:$D,3,FALSE),0) -> 0 | E25: =IFERROR(VLOOKUP(B25,Ingredientes!$B:$C,2,FALSE),0) -> 0 | F25: =C25*E25 -> 0
D26: =IFERROR(VLOOKUP(B26,Ingredientes!$B:$D,3,FALSE),0) -> 0 | E26: =IFERROR(VLOOKUP(B26,Ingredientes!$B:$C,2,FALSE),0) -> 0 | F26: =C26*E26 -> 0
... D30: =IFERROR(VLOOKUP(B30,Ingredientes!$B:$D,3,FALSE),0) -> 0 | E30: =IFERROR(VLOOKUP(B30,Ingredientes!$B:$C,2,FALSE),0) -> 0 | F30: =C30*E30 -> 0
F31: =SUM(F6:F30) -> 0
H32: CALCULADORA DE AYUDA
B33: CONCEPTO | C33: Horas x unidad | D33: Costo por hora | E33: TOTAL | H33: MINUTOS | I33: HORAS
B34: MANO DE OBRA | D34: =MO!E18 -> 1100000 | E34: =C34*D34 -> 0 | I34: =H34/60 -> 0
B36: CONCEPTO | C36: Costos fijos por receta
B37: COSTOS FIJOS | C37: =VLOOKUP(B2,CIF!F:I,4,FALSE)

Sheet 11
B2: =MENU!B14 -> Nombre de la receta 11
B4: COSTO DE LOS INGREDIENTES
B5: Ingrediente | C5: Cantidad | D5: U. medida | E5: Precio unitario | F5: Total | H5: RESUMEN FINAL
D6: =IFERROR(VLOOKUP(B6,Ingredientes!$B:$D,3,FALSE),0) -> 0 | E6: =IFERROR(VLOOKUP(B6,Ingredientes!$B:$C,2,FALSE),0) -> 0 | F6: =C6*E6 -> 0 | H6: Costo ingredientes: | I6: =F31 -> 0
D7: =IFERROR(VLOOKUP(B7,Ingredientes!$B:$D,3,FALSE),0) -> 0 | E7: =IFERROR(VLOOKUP(B7,Ingredientes!$B:$C,2,FALSE),0) -> 0 | F7: =C7*E7 -> 0 | H7: Costo laboral: | I7: =E34 -> 0
D8: =IFERROR(VLOOKUP(B8,Ingredientes!$B:$D,3,FALSE),0) -> 0 | E8: =IFERROR(VLOOKUP(B8,Ingredientes!$B:$C,2,FALSE),0) -> 0 | F8: =C8*E8 -> 0 | H8: Costo fijo: | I8: =C37
D9: =IFERROR(VLOOKUP(B9,Ingredientes!$B:$D,3,FALSE),0) -> 0 | E9: =IFERROR(VLOOKUP(B9,Ingredientes!$B:$C,2,FALSE),0) -> 0 | F9: =C9*E9 -> 0 | H9: Costo Total | I9: =SUM($I$6:$I$8) -> 0
D10: =IFERROR(VLOOKUP(B10,Ingredientes!$B:$D,3,FALSE),0) -> 0 | E10: =IFERROR(VLOOKUP(B10,Ingredientes!$B:$C,2,FALSE),0) -> 0 | F10: =C10*E10 -> 0
D11: =IFERROR(VLOOKUP(B11,Ingredientes!$B:$D,3,FALSE),0) -> 0 | E11: =IFERROR(VLOOKUP(B11,Ingredientes!$B:$C,2,FALSE),0) -> 0 | F11: =C11*E11 -> 0 | H11: Precio de venta | I11: 5000
D12: =IFERROR(VLOOKUP(B12,Ingredientes!$B:$D,3,FALSE),0) -> 0 | E12: =IFERROR(VLOOKUP(B12,Ingredientes!$B:$C,2,FALSE),0) -> 0 | F12: =C12*E12 -> 0 | H12: Utilidad en $ | I12: =I11-I9 -> 5000
D13: =IFERROR(VLOOKUP(B13,Ingredientes!$B:$D,3,FALSE),0) -> 0 | E13: =IFERROR(VLOOKUP(B13,Ingredientes!$B:$C,2,FALSE),0) -> 0 | F13: =C13*E13 -> 0 | H13: Utilidad en $ | I13: =I12/I11 -> 1
D14: =IFERROR(VLOOKUP(B14,Ingredientes!$B:$D,3,FALSE),0) -> 0 | E14: =IFERROR(VLOOKUP(B14,Ingredientes!$B:$C,2,FALSE),0) -> 0 | F14: =C14*E14 -> 0 | H14: Punto de equilibrio (u) | I14: =CIF!C67/(I11-I6-I7) -> 236
D15: =IFERROR(VLOOKUP(B15,Ingredientes!$B:$D,3,FALSE),0) -> 0 | E15: =IFERROR(VLOOKUP(B15,Ingredientes!$B:$C,2,FALSE),0) -> 0 | F15: =C15*E15 -> 0
D16: =IFERROR(VLOOKUP(B16,Ingredientes!$B:$D,3,FALSE),0) -> 0 | E16: =IFERROR(VLOOKUP(B16,Ingredientes!$B:$C,2,FALSE),0) -> 0 | F16: =C16*E16 -> 0
D17: =IFERROR(VLOOKUP(B17,Ingredientes!$B:$D,3,FALSE),0) -> 0 | E17: =IFERROR(VLOOKUP(B17,Ingredientes!$B:$C,2,FALSE),0) -> 0 | F17: =C17*E17 -> 0
D18: =IFERROR(VLOOKUP(B18,Ingredientes!$B:$D,3,FALSE),0) -> 0 | E18: =IFERROR(VLOOKUP(B18,Ingredientes!$B:$C,2,FALSE),0) -> 0 | F18: =C18*E18 -> 0
D19: =IFERROR(VLOOKUP(B19,Ingredientes!$B:$D,3,FALSE),0) -> 0 | E19: =IFERROR(VLOOKUP(B19,Ingredientes!$B:$C,2,FALSE),0) -> 0 | F19: =C19*E19 -> 0
D20: =IFERROR(VLOOKUP(B20,Ingredientes!$B:$D,3,FALSE),0) -> 0 | E20: =IFERROR(VLOOKUP(B20,Ingredientes!$B:$C,2,FALSE),0) -> 0 | F20: =C20*E20 -> 0
D21: =IFERROR(VLOOKUP(B21,Ingredientes!$B:$D,3,FALSE),0) -> 0 | E21: =IFERROR(VLOOKUP(B21,Ingredientes!$B:$C,2,FALSE),0) -> 0 | F21: =C21*E21 -> 0
D22: =IFERROR(VLOOKUP(B22,Ingredientes!$B:$D,3,FALSE),0) -> 0 | E22: =IFERROR(VLOOKUP(B22,Ingredientes!$B:$C,2,FALSE),0) -> 0 | F22: =C22*E22 -> 0
D23: =IFERROR(VLOOKUP(B23,Ingredientes!$B:$D,3,FALSE),0) -> 0 | E23: =IFERROR(VLOOKUP(B23,Ingredientes!$B:$C,2,FALSE),0) -> 0 | F23: =C23*E23 -> 0
D24: =IFERROR(VLOOKUP(B24,Ingredientes!$B:$D,3,FALSE),0) -> 0 | E24: =IFERROR(VLOOKUP(B24,Ingredientes!$B:$C,2,FALSE),0) -> 0 | F24: =C24*E24 -> 0
D25: =IFERROR(VLOOKUP(B25,Ingredientes!$B:$D,3,FALSE),0) -> 0 | E25: =IFERROR(VLOOKUP(B25,Ingredientes!$B:$C,2,FALSE),0) -> 0 | F25: =C25*E25 -> 0
D26: =IFERROR(VLOOKUP(B26,Ingredientes!$B:$D,3,FALSE),0) -> 0 | E26: =IFERROR(VLOOKUP(B26,Ingredientes!$B:$C,2,FALSE),0) -> 0 | F26: =C26*E26 -> 0
... D30: =IFERROR(VLOOKUP(B30,Ingredientes!$B:$D,3,FALSE),0) -> 0 | E30: =IFERROR(VLOOKUP(B30,Ingredientes!$B:$C,2,FALSE),0) -> 0 | F30: =C30*E30 -> 0
F31: =SUM(F6:F30) -> 0
H32: CALCULADORA DE AYUDA
B33: CONCEPTO | C33: Horas x unidad | D33: Costo por hora | E33: TOTAL | H33: MINUTOS | I33: HORAS
B34: MANO DE OBRA | D34: =MO!E18 -> 1100000 | E34: =C34*D34 -> 0 | I34: =H34/60 -> 0
B36: CONCEPTO | C36: Costos fijos por receta
B37: COSTOS FIJOS | C37: =VLOOKUP(B2,CIF!F:I,4,FALSE)

Sheet 12
B2: =MENU!B15 -> Nombre de la receta 12
B4: COSTO DE LOS INGREDIENTES
B5: Ingrediente | C5: Cantidad | D5: U. medida | E5: Precio unitario | F5: Total | H5: RESUMEN FINAL
D6: =IFERROR(VLOOKUP(B6,Ingredientes!$B:$D,3,FALSE),0) -> 0 | E6: =IFERROR(VLOOKUP(B6,Ingredientes!$B:$C,2,FALSE),0) -> 0 | F6: =C6*E6 -> 0 | H6: Costo ingredientes: | I6: =F31 -> 0
D7: =IFERROR(VLOOKUP(B7,Ingredientes!$B:$D,3,FALSE),0) -> 0 | E7: =IFERROR(VLOOKUP(B7,Ingredientes!$B:$C,2,FALSE),0) -> 0 | F7: =C7*E7 -> 0 | H7: Costo laboral: | I7: =E34 -> 0
D8: =IFERROR(VLOOKUP(B8,Ingredientes!$B:$D,3,FALSE),0) -> 0 | E8: =IFERROR(VLOOKUP(B8,Ingredientes!$B:$C,2,FALSE),0) -> 0 | F8: =C8*E8 -> 0 | H8: Costo fijo: | I8: =C37
D9: =IFERROR(VLOOKUP(B9,Ingredientes!$B:$D,3,FALSE),0) -> 0 | E9: =IFERROR(VLOOKUP(B9,Ingredientes!$B:$C,2,FALSE),0) -> 0 | F9: =C9*E9 -> 0 | H9: Costo Total | I9: =SUM($I$6:$I$8) -> 0
D10: =IFERROR(VLOOKUP(B10,Ingredientes!$B:$D,3,FALSE),0) -> 0 | E10: =IFERROR(VLOOKUP(B10,Ingredientes!$B:$C,2,FALSE),0) -> 0 | F10: =C10*E10 -> 0
D11: =IFERROR(VLOOKUP(B11,Ingredientes!$B:$D,3,FALSE),0) -> 0 | E11: =IFERROR(VLOOKUP(B11,Ingredientes!$B:$C,2,FALSE),0) -> 0 | F11: =C11*E11 -> 0 | H11: Precio de venta | I11: 5000
D12: =IFERROR(VLOOKUP(B12,Ingredientes!$B:$D,3,FALSE),0) -> 0 | E12: =IFERROR(VLOOKUP(B12,Ingredientes!$B:$C,2,FALSE),0) -> 0 | F12: =C12*E12 -> 0 | H12: Utilidad en $ | I12: =I11-I9 -> 5000
D13: =IFERROR(VLOOKUP(B13,Ingredientes!$B:$D,3,FALSE),0) -> 0 | E13: =IFERROR(VLOOKUP(B13,Ingredientes!$B:$C,2,FALSE),0) -> 0 | F13: =C13*E13 -> 0 | H13: Utilidad en $ | I13: =I12/I11 -> 1
D14: =IFERROR(VLOOKUP(B14,Ingredientes!$B:$D,3,FALSE),0) -> 0 | E14: =IFERROR(VLOOKUP(B14,Ingredientes!$B:$C,2,FALSE),0) -> 0 | F14: =C14*E14 -> 0 | H14: Punto de equilibrio (u) | I14: =CIF!C67/(I11-I6-I7) -> 236
D15: =IFERROR(VLOOKUP(B15,Ingredientes!$B:$D,3,FALSE),0) -> 0 | E15: =IFERROR(VLOOKUP(B15,Ingredientes!$B:$C,2,FALSE),0) -> 0 | F15: =C15*E15 -> 0
D16: =IFERROR(VLOOKUP(B16,Ingredientes!$B:$D,3,FALSE),0) -> 0 | E16: =IFERROR(VLOOKUP(B16,Ingredientes!$B:$C,2,FALSE),0) -> 0 | F16: =C16*E16 -> 0
D17: =IFERROR(VLOOKUP(B17,Ingredientes!$B:$D,3,FALSE),0) -> 0 | E17: =IFERROR(VLOOKUP(B17,Ingredientes!$B:$C,2,FALSE),0) -> 0 | F17: =C17*E17 -> 0
D18: =IFERROR(VLOOKUP(B18,Ingredientes!$B:$D,3,FALSE),0) -> 0 | E18: =IFERROR(VLOOKUP(B18,Ingredientes!$B:$C,2,FALSE),0) -> 0 | F18: =C18*E18 -> 0
D19: =IFERROR(VLOOKUP(B19,Ingredientes!$B:$D,3,FALSE),0) -> 0 | E19: =IFERROR(VLOOKUP(B19,Ingredientes!$B:$C,2,FALSE),0) -> 0 | F19: =C19*E19 -> 0
D20: =IFERROR(VLOOKUP(B20,Ingredientes!$B:$D,3,FALSE),0) -> 0 | E20: =IFERROR(VLOOKUP(B20,Ingredientes!$B:$C,2,FALSE),0) -> 0 | F20: =C20*E20 -> 0
D21: =IFERROR(VLOOKUP(B21,Ingredientes!$B:$D,3,FALSE),0) -> 0 | E21: =IFERROR(VLOOKUP(B21,Ingredientes!$B:$C,2,FALSE),0) -> 0 | F21: =C21*E21 -> 0
D22: =IFERROR(VLOOKUP(B22,Ingredientes!$B:$D,3,FALSE),0) -> 0 | E22: =IFERROR(VLOOKUP(B22,Ingredientes!$B:$C,2,FALSE),0) -> 0 | F22: =C22*E22 -> 0
D23: =IFERROR(VLOOKUP(B23,Ingredientes!$B:$D,3,FALSE),0) -> 0 | E23: =IFERROR(VLOOKUP(B23,Ingredientes!$B:$C,2,FALSE),0) -> 0 | F23: =C23*E23 -> 0
D24: =IFERROR(VLOOKUP(B24,Ingredientes!$B:$D,3,FALSE),0) -> 0 | E24: =IFERROR(VLOOKUP(B24,Ingredientes!$B:$C,2,FALSE),0) -> 0 | F24: =C24*E24 -> 0
D25: =IFERROR(VLOOKUP(B25,Ingredientes!$B:$D,3,FALSE),0) -> 0 | E25: =IFERROR(VLOOKUP(B25,Ingredientes!$B:$C,2,FALSE),0) -> 0 | F25: =C25*E25 -> 0
D26: =IFERROR(VLOOKUP(B26,Ingredientes!$B:$D,3,FALSE),0) -> 0 | E26: =IFERROR(VLOOKUP(B26,Ingredientes!$B:$C,2,FALSE),0) -> 0 | F26: =C26*E26 -> 0
... D30: =IFERROR(VLOOKUP(B30,Ingredientes!$B:$D,3,FALSE),0) -> 0 | E30: =IFERROR(VLOOKUP(B30,Ingredientes!$B:$C,2,FALSE),0) -> 0 | F30: =C30*E30 -> 0
F31: =SUM(F6:F30) -> 0
H32: CALCULADORA DE AYUDA
B33: CONCEPTO | C33: Horas x unidad | D33: Costo por hora | E33: TOTAL | H33: MINUTOS | I33: HORAS
B34: MANO DE OBRA | D34: =MO!E18 -> 1100000 | E34: =C34*D34 -> 0 | I34: =H34/60 -> 0
B36: CONCEPTO | C36: Costos fijos por receta
B37: COSTOS FIJOS | C37: =VLOOKUP(B2,CIF!F:I,4,FALSE)

Sheet 13
B2: =MENU!B16 -> Nombre de la receta 13
B4: COSTO DE LOS INGREDIENTES
B5: Ingrediente | C5: Cantidad | D5: U. medida | E5: Precio unitario | F5: Total | H5: RESUMEN FINAL
D6: =IFERROR(VLOOKUP(B6,Ingredientes!$B:$D,3,FALSE),0) -> 0 | E6: =IFERROR(VLOOKUP(B6,Ingredientes!$B:$C,2,FALSE),0) -> 0 | F6: =C6*E6 -> 0 | H6: Costo ingredientes: | I6: =F31 -> 0
